Workbook
Name Lista_Gastos: OFFSET(Abril!$J$14,0,0,COUNTA(Abril!$J$14:$J$41))
Name Lista_Gastos: OFFSET(Agosto!$J$14,0,0,COUNTA(Agosto!$J$14:$J$41))
Name Lista_Gastos: OFFSET(Diciembre!$J$14,0,0,COUNTA(Diciembre!$J$14:$J$41))
Name Lista_Gastos: OFFSET(Febrero!$J$14,0,0,COUNTA(Febrero!$J$14:$J$41))
Name Lista_Gastos: OFFSET(Julio!$J$14,0,0,COUNTA(Julio!$J$14:$J$41))
Name Lista_Gastos: OFFSET(Junio!$J$14,0,0,COUNTA(Junio!$J$14:$J$41))
Name Lista_Gastos: OFFSET(Marzo!$J$14,0,0,COUNTA(Marzo!$J$14:$J$41))
Name Lista_Gastos: OFFSET(Mayo!$J$14,0,0,COUNTA(Mayo!$J$14:$J$41))
Name Lista_Gastos: OFFSET(Noviembre!$J$14,0,0,COUNTA(Noviembre!$J$14:$J$41))
Name Lista_Gastos: OFFSET(Octubre!$J$14,0,0,COUNTA(Octubre!$J$14:$J$41))
Name Lista_Gastos: OFFSET(Setiembre!$J$14,0,0,COUNTA(Setiembre!$J$14:$J$41))
Name Lista_Gastos: OFFSET(Enero!$J$14,0,0,COUNTA(Enero!$J$14:$J$41))

Sheet Anual
B2: ="PRESUPUESTO ANUAL "&L2 -> PRESUPUESTO ANUAL 2023 | I2: Escoger el año | L2: 2023
F5: RESUMEN DE FLUJO DE EFECTIVO | J5: RESUMEN DE FLUJO DE EFECTIVO REAL MENSUAL
F6: CATEGORIA | G6: PRESUPUESTO | H6: REAL | J6: ENE | K6: FEB | L6: MAR | N6: ABR | O6: MAY | P6: JUN | R6: JUL | S6: AGO | T6: SET | V6: OCT | W6: NOV | X6: DIC
F7: Ingresos | G7: =OFFSET($B$38,0,MATCH($F7,$B$24:$X$24,0)) -> 10300 | H7: =OFFSET($B$38,0,MATCH($F7,$B$24:$X$24,0)+1) -> 9270 | J7: =OFFSET($B$25,COLUMN(A1),MATCH($F7,$B$24:$X$24,0)+1) -> 9270 | K7: =OFFSET($B$25,COLUMN(B1),MATCH($F7,$B$24:$X$24,0)+1) -> 0 | L7: =OFFSET($B$25,COLUMN(C1),MATCH($F7,$B$24:$X$24,0)+1) -> 0 | N7: =OFFSET($B$25,COLUMN(D1),MATCH($F7,$B$24:$X$24,0)+1) -> 0 | O7: =OFFSET($B$25,COLUMN(E1),MATCH($F7,$B$24:$X$24,0)+1) -> 0 | P7: =OFFSET($B$25,COLUMN(F1),MATCH($F7,$B$24:$X$24,0)+1) -> 0 | R7: =OFFSET($B$25,COLUMN(G1),MATCH($F7,$B$24:$X$24,0)+1) -> 0 | S7: =OFFSET($B$25,COLUMN(H1),MATCH($F7,$B$24:$X$24,0)+1) -> 0 | T7: =OFFSET($B$25,COLUMN(I1),MATCH($F7,$B$24:$X$24,0)+1) -> 0 | V7: =OFFSET($B$25,COLUMN(J1),MATCH($F7,$B$24:$X$24,0)+1) -> 0 | W7: =OFFSET($B$25,COLUMN(K1),MATCH($F7,$B$24:$X$24,0)+1) -> 0 | X7: =OFFSET($B$25,COLUMN(L1),MATCH($F7,$B$24:$X$24,0)+1) -> 0
F8: Facturas | G8: =OFFSET($B$38,0,MATCH($F8,$B$24:$X$24,0)) -> 1730 | H8: =OFFSET($B$38,0,MATCH($F8,$B$24:$X$24,0)+1) -> 1685 | J8: =OFFSET($B$25,COLUMN(A2),MATCH($F8,$B$24:$X$24,0)+1) -> 1685 | K8: =OFFSET($B$25,COLUMN(B2),MATCH($F8,$B$24:$X$24,0)+1) -> 0 | L8: =OFFSET($B$25,COLUMN(C2),MATCH($F8,$B$24:$X$24,0)+1) -> 0 | N8: =OFFSET($B$25,COLUMN(D2),MATCH($F8,$B$24:$X$24,0)+1) -> 0 | O8: =OFFSET($B$25,COLUMN(E2),MATCH($F8,$B$24:$X$24,0)+1) -> 0 | P8: =OFFSET($B$25,COLUMN(F2),MATCH($F8,$B$24:$X$24,0)+1) -> 0 | R8: =OFFSET($B$25,COLUMN(G2),MATCH($F8,$B$24:$X$24,0)+1) -> 0 | S8: =OFFSET($B$25,COLUMN(H2),MATCH($F8,$B$24:$X$24,0)+1) -> 0 | T8: =OFFSET($B$25,COLUMN(I2),MATCH($F8,$B$24:$X$24,0)+1) -> 0 | V8: =OFFSET($B$25,COLUMN(J2),MATCH($F8,$B$24:$X$24,0)+1) -> 0 | W8: =OFFSET($B$25,COLUMN(K2),MATCH($F8,$B$24:$X$24,0)+1) -> 0 | X8: =OFFSET($B$25,COLUMN(L2),MATCH($F8,$B$24:$X$24,0)+1) -> 0
F9: Gastos | G9: =OFFSET($B$38,0,MATCH($F9,$B$24:$X$24,0)) -> 1630 | H9: =OFFSET($B$38,0,MATCH($F9,$B$24:$X$24,0)+1) -> 1355 | J9: =OFFSET($B$25,COLUMN(A3),MATCH($F9,$B$24:$X$24,0)+1) -> 1355 | K9: =OFFSET($B$25,COLUMN(B3),MATCH($F9,$B$24:$X$24,0)+1) -> 0 | L9: =OFFSET($B$25,COLUMN(C3),MATCH($F9,$B$24:$X$24,0)+1) -> 0 | N9: =OFFSET($B$25,COLUMN(D3),MATCH($F9,$B$24:$X$24,0)+1) -> 0 | O9: =OFFSET($B$25,COLUMN(E3),MATCH($F9,$B$24:$X$24,0)+1) -> 0 | P9: =OFFSET($B$25,COLUMN(F3),MATCH($F9,$B$24:$X$24,0)+1) -> 0 | R9: =OFFSET($B$25,COLUMN(G3),MATCH($F9,$B$24:$X$24,0)+1) -> 0 | S9: =OFFSET($B$25,COLUMN(H3),MATCH($F9,$B$24:$X$24,0)+1) -> 0 | T9: =OFFSET($B$25,COLUMN(I3),MATCH($F9,$B$24:$X$24,0)+1) -> 0 | V9: =OFFSET($B$25,COLUMN(J3),MATCH($F9,$B$24:$X$24,0)+1) -> 0 | W9: =OFFSET($B$25,COLUMN(K3),MATCH($F9,$B$24:$X$24,0)+1) -> 0 | X9: =OFFSET($B$25,COLUMN(L3),MATCH($F9,$B$24:$X$24,0)+1) -> 0
F10: Créditos | G10: =OFFSET($B$38,0,MATCH($F10,$B$24:$X$24,0)) -> 4200 | H10: =OFFSET($B$38,0,MATCH($F10,$B$24:$X$24,0)+1) -> 4100 | J10: =OFFSET($B$25,COLUMN(A4),MATCH($F10,$B$24:$X$24,0)+1) -> 4100 | K10: =OFFSET($B$25,COLUMN(B4),MATCH($F10,$B$24:$X$24,0)+1) -> 0 | L10: =OFFSET($B$25,COLUMN(C4),MATCH($F10,$B$24:$X$24,0)+1) -> 0 | N10: =OFFSET($B$25,COLUMN(D4),MATCH($F10,$B$24:$X$24,0)+1) -> 0 | O10: =OFFSET($B$25,COLUMN(E4),MATCH($F10,$B$24:$X$24,0)+1) -> 0 | P10: =OFFSET($B$25,COLUMN(F4),MATCH($F10,$B$24:$X$24,0)+1) -> 0 | R10: =OFFSET($B$25,COLUMN(G4),MATCH($F10,$B$24:$X$24,0)+1) -> 0 | S10: =OFFSET($B$25,COLUMN(H4),MATCH($F10,$B$24:$X$24,0)+1) -> 0 | T10: =OFFSET($B$25,COLUMN(I4),MATCH($F10,$B$24:$X$24,0)+1) -> 0 | V10: =OFFSET($B$25,COLUMN(J4),MATCH($F10,$B$24:$X$24,0)+1) -> 0 | W10: =OFFSET($B$25,COLUMN(K4),MATCH($F10,$B$24:$X$24,0)+1) -> 0 | X10: =OFFSET($B$25,COLUMN(L4),MATCH($F10,$B$24:$X$24,0)+1) -> 0
F11: Ahorros | G11: =OFFSET($B$38,0,MATCH($F11,$B$24:$X$24,0)) -> 1175 | H11: =OFFSET($B$38,0,MATCH($F11,$B$24:$X$24,0)+1) -> 1075 | J11: =OFFSET($B$25,COLUMN(A5),MATCH($F11,$B$24:$X$24,0)+1) -> 1075 | K11: =OFFSET($B$25,COLUMN(B5),MATCH($F11,$B$24:$X$24,0)+1) -> 0 | L11: =OFFSET($B$25,COLUMN(C5),MATCH($F11,$B$24:$X$24,0)+1) -> 0 | N11: =OFFSET($B$25,COLUMN(D5),MATCH($F11,$B$24:$X$24,0)+1) -> 0 | O11: =OFFSET($B$25,COLUMN(E5),MATCH($F11,$B$24:$X$24,0)+1) -> 0 | P11: =OFFSET($B$25,COLUMN(F5),MATCH($F11,$B$24:$X$24,0)+1) -> 0 | R11: =OFFSET($B$25,COLUMN(G5),MATCH($F11,$B$24:$X$24,0)+1) -> 0 | S11: =OFFSET($B$25,COLUMN(H5),MATCH($F11,$B$24:$X$24,0)+1) -> 0 | T11: =OFFSET($B$25,COLUMN(I5),MATCH($F11,$B$24:$X$24,0)+1) -> 0 | V11: =OFFSET($B$25,COLUMN(J5),MATCH($F11,$B$24:$X$24,0)+1) -> 0 | W11: =OFFSET($B$25,COLUMN(K5),MATCH($F11,$B$24:$X$24,0)+1) -> 0 | X11: =OFFSET($B$25,COLUMN(L5),MATCH($F11,$B$24:$X$24,0)+1) -> 0
F12: Inversiones | G12: =OFFSET($B$38,0,MATCH($F12,$B$24:$X$24,0)) -> 500 | H12: =OFFSET($B$38,0,MATCH($F12,$B$24:$X$24,0)+1) -> 300 | J12: =OFFSET($B$25,COLUMN(A6),MATCH($F12,$B$24:$X$24,0)+1) -> 300 | K12: =OFFSET($B$25,COLUMN(B6),MATCH($F12,$B$24:$X$24,0)+1) -> 0 | L12: =OFFSET($B$25,COLUMN(C6),MATCH($F12,$B$24:$X$24,0)+1) -> 0 | N12: =OFFSET($B$25,COLUMN(D6),MATCH($F12,$B$24:$X$24,0)+1) -> 0 | O12: =OFFSET($B$25,COLUMN(E6),MATCH($F12,$B$24:$X$24,0)+1) -> 0 | P12: =OFFSET($B$25,COLUMN(F6),MATCH($F12,$B$24:$X$24,0)+1) -> 0 | R12: =OFFSET($B$25,COLUMN(G6),MATCH($F12,$B$24:$X$24,0)+1) -> 0 | S12: =OFFSET($B$25,COLUMN(H6),MATCH($F12,$B$24:$X$24,0)+1) -> 0 | T12: =OFFSET($B$25,COLUMN(I6),MATCH($F12,$B$24:$X$24,0)+1) -> 0 | V12: =OFFSET($B$25,COLUMN(J6),MATCH($F12,$B$24:$X$24,0)+1) -> 0 | W12: =OFFSET($B$25,COLUMN(K6),MATCH($F12,$B$24:$X$24,0)+1) -> 0 | X12: =OFFSET($B$25,COLUMN(L6),MATCH($F12,$B$24:$X$24,0)+1) -> 0
F13: SALDO | G13: =G7-SUM(G8:G12) -> 1065 | H13: =H7-SUM(H8:H12) -> 755 | J13: =J7-SUM(J8:J12) -> 755 | K13: =K7-SUM(K8:K12) -> 0 | L13: =L7-SUM(L8:L12) -> 0 | N13: =N7-SUM(N8:N12) -> 0 | O13: =O7-SUM(O8:O12) -> 0 | P13: =P7-SUM(P8:P12) -> 0 | R13: =R7-SUM(R8:R12) -> 0 | S13: =S7-SUM(S8:S12) -> 0 | T13: =T7-SUM(T8:T12) -> 0 | V13: =V7-SUM(V8:V12) -> 0 | W13: =W7-SUM(W8:W12) -> 0 | X13: =X7-SUM(X8:X12) -> 0
F14: DIFERENCIA | H14: =G13-H13 -> 310 | J14: SALDO TRIMESTRE 1 | L14: =SUM(J13:L13) -> 755 | N14: SALDO TRIMESTRE 2 | P14: =SUM(N13:P13) -> 0 | R14: SALDO TRIMESTRE 3 | T14: =SUM(R13:T13) -> 0 | V14: SALDO TRIMESTRE 4 | X14: =SUM(V13:X13) -> 0
F16: RESUMEN FINANCIERO | J16: RESUMEN FINANCIERO REAL MENSUAL
F17: CATEGORIA | G17: PRESUPUESTO | H17: REAL | J17: ENE | K17: FEB | L17: MAR | N17: ABR | O17: MAY | P17: JUN | R17: JUL | S17: AGO | T17: SET | V17: OCT | W17: NOV | X17: DIC
F18: Ingresos | G18: =OFFSET($B$38,0,MATCH($F18,$B$24:$X$24,0)) -> 10300 | H18: =OFFSET($B$38,0,MATCH($F18,$B$24:$X$24,0)+1) -> 9270 | J18: =OFFSET($B$25,COLUMN(A12),MATCH($F18,$B$24:$X$24,0)+1) -> 9270 | K18: =OFFSET($B$25,COLUMN(B12),MATCH($F18,$B$24:$X$24,0)+1) -> 0 | L18: =OFFSET($B$25,COLUMN(C12),MATCH($F18,$B$24:$X$24,0)+1) -> 0 | N18: =OFFSET($B$25,COLUMN(D12),MATCH($F18,$B$24:$X$24,0)+1) -> 0 | O18: =OFFSET($B$25,COLUMN(E12),MATCH($F18,$B$24:$X$24,0)+1) -> 0 | P18: =OFFSET($B$25,COLUMN(F12),MATCH($F18,$B$24:$X$24,0)+1) -> 0 | R18: =OFFSET($B$25,COLUMN(G12),MATCH($F18,$B$24:$X$24,0)+1) -> 0 | S18: =OFFSET($B$25,COLUMN(H12),MATCH($F18,$B$24:$X$24,0)+1) -> 0 | T18: =OFFSET($B$25,COLUMN(I12),MATCH($F18,$B$24:$X$24,0)+1) -> 0 | V18: =OFFSET($B$25,COLUMN(J12),MATCH($F18,$B$24:$X$24,0)+1) -> 0 | W18: =OFFSET($B$25,COLUMN(K12),MATCH($F18,$B$24:$X$24,0)+1) -> 0 | X18: =OFFSET($B$25,COLUMN(L12),MATCH($F18,$B$24:$X$24,0)+1) -> 0
F19: Facturas | G19: =OFFSET($B$38,0,MATCH($F19,$B$24:$X$24,0)) -> 1730 | H19: =OFFSET($B$38,0,MATCH($F19,$B$24:$X$24,0)+1) -> 1685 | J19: =OFFSET($B$25,COLUMN(A13),MATCH($F19,$B$24:$X$24,0)+1) -> 1685 | K19: =OFFSET($B$25,COLUMN(B13),MATCH($F19,$B$24:$X$24,0)+1) -> 0 | L19: =OFFSET($B$25,COLUMN(C13),MATCH($F19,$B$24:$X$24,0)+1) -> 0 | N19: =OFFSET($B$25,COLUMN(D13),MATCH($F19,$B$24:$X$24,0)+1) -> 0 | O19: =OFFSET($B$25,COLUMN(E13),MATCH($F19,$B$24:$X$24,0)+1) -> 0 | P19: =OFFSET($B$25,COLUMN(F13),MATCH($F19,$B$24:$X$24,0)+1) -> 0 | R19: =OFFSET($B$25,COLUMN(G13),MATCH($F19,$B$24:$X$24,0)+1) -> 0 | S19: =OFFSET($B$25,COLUMN(H13),MATCH($F19,$B$24:$X$24,0)+1) -> 0 | T19: =OFFSET($B$25,COLUMN(I13),MATCH($F19,$B$24:$X$24,0)+1) -> 0 | V19: =OFFSET($B$25,COLUMN(J13),MATCH($F19,$B$24:$X$24,0)+1) -> 0 | W19: =OFFSET($B$25,COLUMN(K13),MATCH($F19,$B$24:$X$24,0)+1) -> 0 | X19: =OFFSET($B$25,COLUMN(L13),MATCH($F19,$B$24:$X$24,0)+1) -> 0
F20: Gastos | G20: =OFFSET($B$38,0,MATCH($F20,$B$24:$X$24,0)) -> 1630 | H20: =OFFSET($B$38,0,MATCH($F20,$B$24:$X$24,0)+1) -> 1355 | J20: =OFFSET($B$25,COLUMN(A14),MATCH($F20,$B$24:$X$24,0)+1) -> 1355 | K20: =OFFSET($B$25,COLUMN(B14),MATCH($F20,$B$24:$X$24,0)+1) -> 0 | L20: =OFFSET($B$25,COLUMN(C14),MATCH($F20,$B$24:$X$24,0)+1) -> 0 | N20: =OFFSET($B$25,COLUMN(D14),MATCH($F20,$B$24:$X$24,0)+1) -> 0 | O20: =OFFSET($B$25,COLUMN(E14),MATCH($F20,$B$24:$X$24,0)+1) -> 0 | P20: =OFFSET($B$25,COLUMN(F14),MATCH($F20,$B$24:$X$24,0)+1) -> 0 | R20: =OFFSET($B$25,COLUMN(G14),MATCH($F20,$B$24:$X$24,0)+1) -> 0 | S20: =OFFSET($B$25,COLUMN(H14),MATCH($F20,$B$24:$X$24,0)+1) -> 0 | T20: =OFFSET($B$25,COLUMN(I14),MATCH($F20,$B$24:$X$24,0)+1) -> 0 | V20: =OFFSET($B$25,COLUMN(J14),MATCH($F20,$B$24:$X$24,0)+1) -> 0 | W20: =OFFSET($B$25,COLUMN(K14),MATCH($F20,$B$24:$X$24,0)+1) -> 0 | X20: =OFFSET($B$25,COLUMN(L14),MATCH($F20,$B$24:$X$24,0)+1) -> 0
F21: INGRESO NETO | G21: =G18-G19-G20 -> 6940 | H21: =H18-H19-H20 -> 6230 | J21: =J18-J19-J20 -> 6230 | K21: =K18-K19-K20 -> 0 | L21: =L18-L19-L20 -> 0 | N21: =N18-N19-N20 -> 0 | O21: =O18-O19-O20 -> 0 | P21: =P18-P19-P20 -> 0 | R21: =R18-R19-R20 -> 0 | S21: =S18-S19-S20 -> 0 | T21: =T18-T19-T20 -> 0 | V21: =V18-V19-V20 -> 0 | W21: =W18-W19-W20 -> 0 | X21: =X18-X19-X20 -> 0
F22: DIFERENCIA | H22: =G21-H21 -> 710 | J22: TOTAL TRIMESTRE 1 | L22: =SUM(J21:L21) -> 6230 | N22: TOTAL TRIMESTRE 2 | P22: =SUM(N21:P21) -> 0 | R22: TOTAL TRIMESTRE 3 | T22: =SUM(R21:T21) -> 0 | V22: TOTAL TRIMESTRE 4 | X22: =SUM(V21:X21) -> 0
B24: INGRESOS | F24: FACTURAS | J24: GASTOS | N24: CRÉDITOS | R24: AHORROS | V24: INVERSIONES
B25: MES | C25: PRESUPUESTO | D25: REAL | F25: MES | G25: PRESUPUESTO | H25: REAL | J25: MES | K25: PRESUPUESTO | L25: REAL | N25: MES | O25: PRESUPUESTO | P25: REAL | R25: MES | S25: PRESUPUESTO | T25: REAL | V25: MES | W25: PRESUPUESTO | X25: REAL
B26: Enero | C26: {=INDIRECT(B26&"!C26")} -> 10300 | D26: {=INDIRECT(B26&"!D26")} -> 9270 | F26: Enero | G26: {=INDIRECT(F26&"!G42")} -> 1730 | H26: {=INDIRECT(F26&"!H42")} -> 1685 | J26: Enero | K26: {=INDIRECT(J26&"!K42")} -> 1630 | L26: {=INDIRECT(J26&"!L42")} -> 1355 | N26: Enero | O26: {=INDIRECT(N26&"!C42")} -> 4200 | P26: {=INDIRECT(N26&"!D42")} -> 4100 | R26: Enero | S26: {=INDIRECT(R26&"!O26")} -> 1175 | T26: {=INDIRECT(R26&"!P26")} -> 1075 | V26: Enero | W26: {=INDIRECT(V26&"!O42")} -> 500 | X26: {=INDIRECT(V26&"!P42")} -> 300
B27: Febrero | C27: {=INDIRECT(B27&"!C26")} -> 0 | D27: {=INDIRECT(B27&"!D26")} -> 0 | F27: Febrero | G27: {=INDIRECT(F27&"!G42")} -> 0 | H27: {=INDIRECT(F27&"!H42")} -> 0 | J27: Febrero | K27: {=INDIRECT(J27&"!K42")} -> 0 | L27: {=INDIRECT(J27&"!L42")} -> 0 | N27: Febrero | O27: {=INDIRECT(N27&"!C42")} -> 0 | P27: {=INDIRECT(N27&"!D42")} -> 0 | R27: Febrero | S27: {=INDIRECT(R27&"!O26")} -> 0 | T27: {=INDIRECT(R27&"!P26")} -> 0 | V27: Febrero | W27: {=INDIRECT(V27&"!O42")} -> 0 | X27: {=INDIRECT(V27&"!P42")} -> 0
B28: Marzo | C28: {=INDIRECT(B28&"!C26")} -> 0 | D28: {=INDIRECT(B28&"!D26")} -> 0 | F28: Marzo | G28: {=INDIRECT(F28&"!G42")} -> 0 | H28: {=INDIRECT(F28&"!H42")} -> 0 | J28: Marzo | K28: {=INDIRECT(J28&"!K42")} -> 0 | L28: {=INDIRECT(J28&"!L42")} -> 0 | N28: Marzo | O28: {=INDIRECT(N28&"!C42")} -> 0 | P28: {=INDIRECT(N28&"!D42")} -> 0 | R28: Marzo | S28: {=INDIRECT(R28&"!O26")} -> 0 | T28: {=INDIRECT(R28&"!P26")} -> 0 | V28: Marzo | W28: {=INDIRECT(V28&"!O42")} -> 0 | X28: {=INDIRECT(V28&"!P42")} -> 0
B29: Abril | C29: {=INDIRECT(B29&"!C26")} -> 0 | D29: {=INDIRECT(B29&"!D26")} -> 0 | F29: Abril | G29: {=INDIRECT(F29&"!G42")} -> 0 | H29: {=INDIRECT(F29&"!H42")} -> 0 | J29: Abril | K29: {=INDIRECT(J29&"!K42")} -> 0 | L29: {=INDIRECT(J29&"!L42")} -> 0 | N29: Abril | O29: {=INDIRECT(N29&"!C42")} -> 0 | P29: {=INDIRECT(N29&"!D42")} -> 0 | R29: Abril | S29: {=INDIRECT(R29&"!O26")} -> 0 | T29: {=INDIRECT(R29&"!P26")} -> 0 | V29: Abril | W29: {=INDIRECT(V29&"!O42")} -> 0 | X29: {=INDIRECT(V29&"!P42")} -> 0
B30: Mayo | C30: {=INDIRECT(B30&"!C26")} -> 0 | D30: {=INDIRECT(B30&"!D26")} -> 0 | F30: Mayo | G30: {=INDIRECT(F30&"!G42")} -> 0 | H30: {=INDIRECT(F30&"!H42")} -> 0 | J30: Mayo | K30: {=INDIRECT(J30&"!K42")} -> 0 | L30: {=INDIRECT(J30&"!L42")} -> 0 | N30: Mayo | O30: {=INDIRECT(N30&"!C42")} -> 0 | P30: {=INDIRECT(N30&"!D42")} -> 0 | R30: Mayo | S30: {=INDIRECT(R30&"!O26")} -> 0 | T30: {=INDIRECT(R30&"!P26")} -> 0 | V30: Mayo | W30: {=INDIRECT(V30&"!O42")} -> 0 | X30: {=INDIRECT(V30&"!P42")} -> 0
B31: Junio | C31: {=INDIRECT(B31&"!C26")} -> 0 | D31: {=INDIRECT(B31&"!D26")} -> 0 | F31: Junio | G31: {=INDIRECT(F31&"!G42")} -> 0 | H31: {=INDIRECT(F31&"!H42")} -> 0 | J31: Junio | K31: {=INDIRECT(J31&"!K42")} -> 0 | L31: {=INDIRECT(J31&"!L42")} -> 0 | N31: Junio | O31: {=INDIRECT(N31&"!C42")} -> 0 | P31: {=INDIRECT(N31&"!D42")} -> 0 | R31: Junio | S31: {=INDIRECT(R31&"!O26")} -> 0 | T31: {=INDIRECT(R31&"!P26")} -> 0 | V31: Junio | W31: {=INDIRECT(V31&"!O42")} -> 0 | X31: {=INDIRECT(V31&"!P42")} -> 0
B32: Julio | C32: {=INDIRECT(B32&"!C26")} -> 0 | D32: {=INDIRECT(B32&"!D26")} -> 0 | F32: Julio | G32: {=INDIRECT(F32&"!G42")} -> 0 | H32: {=INDIRECT(F32&"!H42")} -> 0 | J32: Julio | K32: {=INDIRECT(J32&"!K42")} -> 0 | L32: {=INDIRECT(J32&"!L42")} -> 0 | N32: Julio | O32: {=INDIRECT(N32&"!C42")} -> 0 | P32: {=INDIRECT(N32&"!D42")} -> 0 | R32: Julio | S32: {=INDIRECT(R32&"!O26")} -> 0 | T32: {=INDIRECT(R32&"!P26")} -> 0 | V32: Julio | W32: {=INDIRECT(V32&"!O42")} -> 0 | X32: {=INDIRECT(V32&"!P42")} -> 0
B33: Agosto | C33: {=INDIRECT(B33&"!C26")} -> 0 | D33: {=INDIRECT(B33&"!D26")} -> 0 | F33: Agosto | G33: {=INDIRECT(F33&"!G42")} -> 0 | H33: {=INDIRECT(F33&"!H42")} -> 0 | J33: Agosto | K33: {=INDIRECT(J33&"!K42")} -> 0 | L33: {=INDIRECT(J33&"!L42")} -> 0 | N33: Agosto | O33: {=INDIRECT(N33&"!C42")} -> 0 | P33: {=INDIRECT(N33&"!D42")} -> 0 | R33: Agosto | S33: {=INDIRECT(R33&"!O26")} -> 0 | T33: {=INDIRECT(R33&"!P26")} -> 0 | V33: Agosto | W33: {=INDIRECT(V33&"!O42")} -> 0 | X33: {=INDIRECT(V33&"!P42")} -> 0
B34: Setiembre | C34: {=INDIRECT(B34&"!C26")} -> 0 | D34: {=INDIRECT(B34&"!D26")} -> 0 | F34: Setiembre | G34: {=INDIRECT(F34&"!G42")} -> 0 | H34: {=INDIRECT(F34&"!H42")} -> 0 | J34: Setiembre | K34: {=INDIRECT(J34&"!K42")} -> 0 | L34: {=INDIRECT(J34&"!L42")} -> 0 | N34: Setiembre | O34: {=INDIRECT(N34&"!C42")} -> 0 | P34: {=INDIRECT(N34&"!D42")} -> 0 | R34: Setiembre | S34: {=INDIRECT(R34&"!O26")} -> 0 | T34: {=INDIRECT(R34&"!P26")} -> 0 | V34: Setiembre | W34: {=INDIRECT(V34&"!O42")} -> 0 | X34: {=INDIRECT(V34&"!P42")} -> 0
B35: Octubre | C35: {=INDIRECT(B35&"!C26")} -> 0 | D35: {=INDIRECT(B35&"!D26")} -> 0 | F35: Octubre | G35: {=INDIRECT(F35&"!G42")} -> 0 | H35: {=INDIRECT(F35&"!H42")} -> 0 | J35: Octubre | K35: {=INDIRECT(J35&"!K42")} -> 0 | L35: {=INDIRECT(J35&"!L42")} -> 0 | N35: Octubre | O35: {=INDIRECT(N35&"!C42")} -> 0 | P35: {=INDIRECT(N35&"!D42")} -> 0 | R35: Octubre | S35: {=INDIRECT(R35&"!O26")} -> 0 | T35: {=INDIRECT(R35&"!P26")} -> 0 | V35: Octubre | W35: {=INDIRECT(V35&"!O42")} -> 0 | X35: {=INDIRECT(V35&"!P42")} -> 0
B36: Noviembre | C36: {=INDIRECT(B36&"!C26")} -> 0 | D36: {=INDIRECT(B36&"!D26")} -> 0 | F36: Noviembre | G36: {=INDIRECT(F36&"!G42")} -> 0 | H36: {=INDIRECT(F36&"!H42")} -> 0 | J36: Noviembre | K36: {=INDIRECT(J36&"!K42")} -> 0 | L36: {=INDIRECT(J36&"!L42")} -> 0 | N36: Noviembre | O36: {=INDIRECT(N36&"!C42")} -> 0 | P36: {=INDIRECT(N36&"!D42")} -> 0 | R36: Noviembre | S36: {=INDIRECT(R36&"!O26")} -> 0 | T36: {=INDIRECT(R36&"!P26")} -> 0 | V36: Noviembre | W36: {=INDIRECT(V36&"!O42")} -> 0 | X36: {=INDIRECT(V36&"!P42")} -> 0
B37: Diciembre | C37: {=INDIRECT(B37&"!C26")} -> 0 | D37: {=INDIRECT(B37&"!D26")} -> 0 | F37: Diciembre | G37: {=INDIRECT(F37&"!G42")} -> 0 | H37: {=INDIRECT(F37&"!H42")} -> 0 | J37: Diciembre | K37: {=INDIRECT(J37&"!K42")} -> 0 | L37: {=INDIRECT(J37&"!L42")} -> 0 | N37: Diciembre | O37: {=INDIRECT(N37&"!C42")} -> 0 | P37: {=INDIRECT(N37&"!D42")} -> 0 | R37: Diciembre | S37: {=INDIRECT(R37&"!O26")} -> 0 | T37: {=INDIRECT(R37&"!P26")} -> 0 | V37: Diciembre | W37: {=INDIRECT(V37&"!O42")} -> 0 | X37: {=INDIRECT(V37&"!P42")} -> 0
B38: TOTAL | C38: =SUM(C26:C37) -> 10300 | D38: =SUM(D26:D37) -> 9270 | F38: TOTAL | G38: =SUM(G26:G37) -> 1730 | H38: =SUM(H26:H37) -> 1685 | J38: TOTAL | K38: =SUM(K26:K37) -> 1630 | L38: =SUM(L26:L37) -> 1355 | N38: TOTAL | O38: =SUM(O26:O37) -> 4200 | P38: =SUM(P26:P37) -> 4100 | R38: TOTAL | S38: =SUM(S26:S37) -> 1175 | T38: =SUM(T26:T37) -> 1075 | V38: TOTAL | W38: =SUM(W26:W37) -> 500 | X38: =SUM(X26:X37) -> 300
B39: DIFERENCIA | D39: =C38-D38 -> 1030 | F39: DIFERENCIA | H39: =G38-H38 -> 45 | J39: DIFERENCIA | L39: =K38-L38 -> 275 | N39: DIFERENCIA | P39: =O38-P38 -> 100 | R39: DIFERENCIA | T39: =S38-T38 -> 100 | V39: DIFERENCIA | X39: =W38-X38 -> 200

Sheet Enero
C1: =VALUE(B2) -> 44927 | D1: =EOMONTH(C1,0) -> 44957 | F1: RESUMEN DEL FLUJO DE EFECTIVO
B2: =TEXT(DATE(Anual!$L$2,_xlfn.SHEET()-1,1),"mmmm")&" "&Anual!L2 -> enero 2023 | J2: =H4 -> 9270 | K2: Total Ingresos | R2: REGISTRO DE GASTOS
F3: CATEGORIA | G3: PRESUPUESTO | H3: REAL
B4: RESUMEN FINANCIERO | F4: Ingresos | G4: =C26 -> 10300 | H4: =D26 -> 9270 | J4: =SUM(H5:H9) -> 8515 | K4: Total Gastos
F5: Facturas | G5: =G42 -> 1730 | H5: =H42 -> 1685 | R5: FECHA | S5: CATEGORIA | T5: DESCRIPCIÓN | U5: MONTO
B6: CATEGORIA | C6: PRESUPUESTO | D6: REAL | F6: Gastos | G6: =K42 -> 1630 | H6: =L42 -> 1355 | J6: =G10 -> 1065 | K6: Saldo del presupuesto | R6: 44927 | S6: Restaurantes | T6: Celebración por cumpleaños | U6: 100
B7: Ingresos | C7: =C26 -> 10300 | D7: =D26 -> 9270 | F7: Créditos | G7: =C42 -> 4200 | H7: =D42 -> 4100 | R7: 44927 | S7: Transporte | T7: Visita a familiares | U7: 200
B8: Facturas | C8: =G42 -> 1730 | D8: =H42 -> 1685 | F8: Ahorros | G8: =O26 -> 1175 | H8: =P26 -> 1075 | J8: =H10 -> 755 | K8: Saldo Real | R8: 44928 | S8: Entretenimiento | T8: Película de cine | U8: 150
B9: Gastos | C9: =K42 -> 1630 | D9: =L42 -> 1355 | F9: Inversiones | G9: =O42 -> 500 | H9: =P42 -> 300 | R9: 44929 | S9: Paseos | T9: Centro Comercial | U9: 50
B10: INGRESO NETO | C10: =C7-C8-C9 -> 6940 | D10: =D7-D8-D9 -> 6230 | F10: SALDO | G10: =G4-SUM(G5:G9) -> 1065 | H10: =H4-SUM(H5:H9) -> 755 | J10: =H11 -> 310 | K10: Diferencia de Saldos | R10: 44930 | S10: Médico | T10: Visita al dentista | U10: 10
B11: DIFERENCIA | D11: =C10-D10 -> 710 | F11: DIFERENCIA | H11: =G10-H10 -> 310 | R11: 44930 | S11: Mascotas | T11: Comida de Tommy | U11: 40
R12: 44933 | S12: Ropa | T12: Ropa para verano | U12: 200
B13: INGRESOS | C13: PRESUPUESTO | D13: REAL | F13: FACTURAS | G13: PRESUPUESTO | H13: REAL | J13: GASTOS | K13: PRESUPUESTO | L13: REAL | N13: AHORROS | O13: PRESUPUESTO | P13: REAL | R13: 44933 | S13: Transporte | T13: Pasajes de tren | U13: 15
B14: Empleo | C14: 10000 | D14: 9000 | F14: Alquiler | G14: 1000 | H14: 1000 | J14: Ropa | K14: 250 | L14: =SUMIFS(Tabla_Gastos3[MONTO],Tabla_Gastos3[FECHA],">="&$C$1,Tabla_Gastos3[FECHA],"<="&$D$1,Tabla_Gastos3[CATEGORIA],J14) -> 200 | N14: Departamento | O14: 950 | P14: 900 | R14: 44936 | S14: Regalos | T14: Regalo para mi sobrino | U14: 200
B15: Youtube | C15: 200 | D15: 120 | F15: Internet | G15: 200 | H15: 200 | J15: Restaurantes | K15: 100 | L15: =SUMIFS(Tabla_Gastos3[MONTO],Tabla_Gastos3[FECHA],">="&$C$1,Tabla_Gastos3[FECHA],"<="&$D$1,Tabla_Gastos3[CATEGORIA],J15) -> 150 | N15: Viaje a Cusco | O15: 50 | P15: 50 | R15: 44941 | S15: Gasolina | T15: Por 5 galones | U15: 100
B16: Ventas en línea | C16: 100 | D16: 150 | F16: Teléfono | G16: 80 | H16: 50 | J16: Regalos | K16: 300 | L16: =SUMIFS(Tabla_Gastos3[MONTO],Tabla_Gastos3[FECHA],">="&$C$1,Tabla_Gastos3[FECHA],"<="&$D$1,Tabla_Gastos3[CATEGORIA],J16) -> 200 | N16: Emergencias | O16: 75 | P16: 75 | R16: 44941 | S16: Paseos | T16: Veranear en la playa | U16: 40
F17: Célular | G17: 100 | H17: 80 | J17: Transporte | K17: 300 | L17: =SUMIFS(Tabla_Gastos3[MONTO],Tabla_Gastos3[FECHA],">="&$C$1,Tabla_Gastos3[FECHA],"<="&$D$1,Tabla_Gastos3[CATEGORIA],J17) -> 215 | N17: Otros | O17: 100 | P17: 50 | R17: 44947 | S17: Médico | T17: Chequeo general | U17: 50
F18: Agua | G18: 50 | H18: 40 | J18: Entretenimiento | K18: 200 | L18: =SUMIFS(Tabla_Gastos3[MONTO],Tabla_Gastos3[FECHA],">="&$C$1,Tabla_Gastos3[FECHA],"<="&$D$1,Tabla_Gastos3[CATEGORIA],J18) -> 150 | R18: 44948 | S18: Mascotas | T18: Arena de Tommy | U18: 50
F19: Eléctricidad | G19: 60 | H19: 70 | J19: Paseos | K19: 100 | L19: =SUMIFS(Tabla_Gastos3[MONTO],Tabla_Gastos3[FECHA],">="&$C$1,Tabla_Gastos3[FECHA],"<="&$D$1,Tabla_Gastos3[CATEGORIA],J19) -> 90 | R19: 44951 | S19: Gasolina | T19: Por 5 galones | U19: 100
F20: Gas Doméstico | G20: 50 | H20: 55 | J20: Médico | K20: 100 | L20: =SUMIFS(Tabla_Gastos3[MONTO],Tabla_Gastos3[FECHA],">="&$C$1,Tabla_Gastos3[FECHA],"<="&$D$1,Tabla_Gastos3[CATEGORIA],J20) -> 60 | R20: 44955 | S20: Restaurantes | T20: Celebración de aniversario | U20: 50
F21: Garaje | G21: 100 | H21: 100 | J21: Mascotas | K21: 80 | L21: =SUMIFS(Tabla_Gastos3[MONTO],Tabla_Gastos3[FECHA],">="&$C$1,Tabla_Gastos3[FECHA],"<="&$D$1,Tabla_Gastos3[CATEGORIA],J21) -> 90
F22: Netflix | G22: 40 | H22: 40 | J22: Gasolina | K22: 200 | L22: =SUMIFS(Tabla_Gastos3[MONTO],Tabla_Gastos3[FECHA],">="&$C$1,Tabla_Gastos3[FECHA],"<="&$D$1,Tabla_Gastos3[CATEGORIA],J22) -> 200
F23: Página Web | G23: 50 | H23: 50 | L23: =SUMIFS(Tabla_Gastos3[MONTO],Tabla_Gastos3[FECHA],">="&$C$1,Tabla_Gastos3[FECHA],"<="&$D$1,Tabla_Gastos3[CATEGORIA],J23) -> 0
L24: =SUMIFS(Tabla_Gastos3[MONTO],Tabla_Gastos3[FECHA],">="&$C$1,Tabla_Gastos3[FECHA],"<="&$D$1,Tabla_Gastos3[CATEGORIA],J24) -> 0
L25: =SUMIFS(Tabla_Gastos3[MONTO],Tabla_Gastos3[FECHA],">="&$C$1,Tabla_Gastos3[FECHA],"<="&$D$1,Tabla_Gastos3[CATEGORIA],J25) -> 0
B26: TOTAL | C26: =SUM(C14:C25) -> 10300 | D26: =SUM(D14:D25) -> 9270 | L26: =SUMIFS(Tabla_Gastos3[MONTO],Tabla_Gastos3[FECHA],">="&$C$1,Tabla_Gastos3[FECHA],"<="&$D$1,Tabla_Gastos3[CATEGORIA],J26) -> 0 | N26: TOTAL | O26: =SUM(O14:O25) -> 1175 | P26: =SUM(P14:P25) -> 1075
B27: DIFERENCIA | D27: =C26-D26 -> 1030 | L27: =SUMIFS(Tabla_Gastos3[MONTO],Tabla_Gastos3[FECHA],">="&$C$1,Tabla_Gastos3[FECHA],"<="&$D$1,Tabla_Gastos3[CATEGORIA],J27) -> 0 | N27: DIFERENCIA | P27: =O26-P26 -> 100
L28: =SUMIFS(Tabla_Gastos3[MONTO],Tabla_Gastos3[FECHA],">="&$C$1,Tabla_Gastos3[FECHA],"<="&$D$1,Tabla_Gastos3[CATEGORIA],J28) -> 0
B29: CRÉDITOS | C29: PRESUPUESTO | D29: REAL | L29: =SUMIFS(Tabla_Gastos3[MONTO],Tabla_Gastos3[FECHA],">="&$C$1,Tabla_Gastos3[FECHA],"<="&$D$1,Tabla_Gastos3[CATEGORIA],J29) -> 0 | N29: INVERSIONES | O29: PRESUPUESTO | P29: REAL
B30: Tarjeta Visa Clásica | C30: 500 | D30: 400 | L30: =SUMIFS(Tabla_Gastos3[MONTO],Tabla_Gastos3[FECHA],">="&$C$1,Tabla_Gastos3[FECHA],"<="&$D$1,Tabla_Gastos3[CATEGORIA],J30) -> 0 | N30: Acciones | O30: 400 | P30: 200
B31: Tarjeta CRM | C31: 200 | D31: 300 | L31: =SUMIFS(Tabla_Gastos3[MONTO],Tabla_Gastos3[FECHA],">="&$C$1,Tabla_Gastos3[FECHA],"<="&$D$1,Tabla_Gastos3[CATEGORIA],J31) -> 0 | N31: Terrenos | O31: 100 | P31: 100
B32: Préstamo personal | C32: 1500 | D32: 1600 | L32: =SUMIFS(Tabla_Gastos3[MONTO],Tabla_Gastos3[FECHA],">="&$C$1,Tabla_Gastos3[FECHA],"<="&$D$1,Tabla_Gastos3[CATEGORIA],J32) -> 0
B33: Préstamo Hipotecario | C33: 2000 | D33: 1800 | L33: =SUMIFS(Tabla_Gastos3[MONTO],Tabla_Gastos3[FECHA],">="&$C$1,Tabla_Gastos3[FECHA],"<="&$D$1,Tabla_Gastos3[CATEGORIA],J33) -> 0
L34: =SUMIFS(Tabla_Gastos3[MONTO],Tabla_Gastos3[FECHA],">="&$C$1,Tabla_Gastos3[FECHA],"<="&$D$1,Tabla_Gastos3[CATEGORIA],J34) -> 0
L35: =SUMIFS(Tabla_Gastos3[MONTO],Tabla_Gastos3[FECHA],">="&$C$1,Tabla_Gastos3[FECHA],"<="&$D$1,Tabla_Gastos3[CATEGORIA],J35) -> 0
L36: =SUMIFS(Tabla_Gastos3[MONTO],Tabla_Gastos3[FECHA],">="&$C$1,Tabla_Gastos3[FECHA],"<="&$D$1,Tabla_Gastos3[CATEGORIA],J36) -> 0
L37: =SUMIFS(Tabla_Gastos3[MONTO],Tabla_Gastos3[FECHA],">="&$C$1,Tabla_Gastos3[FECHA],"<="&$D$1,Tabla_Gastos3[CATEGORIA],J37) -> 0
L38: =SUMIFS(Tabla_Gastos3[MONTO],Tabla_Gastos3[FECHA],">="&$C$1,Tabla_Gastos3[FECHA],"<="&$D$1,Tabla_Gastos3[CATEGORIA],J38) -> 0
L39: =SUMIFS(Tabla_Gastos3[MONTO],Tabla_Gastos3[FECHA],">="&$C$1,Tabla_Gastos3[FECHA],"<="&$D$1,Tabla_Gastos3[CATEGORIA],J39) -> 0
L40: =SUMIFS(Tabla_Gastos3[MONTO],Tabla_Gastos3[FECHA],">="&$C$1,Tabla_Gastos3[FECHA],"<="&$D$1,Tabla_Gastos3[CATEGORIA],J40) -> 0
...

Sheet Febrero
C1: =VALUE(B2) -> 44958 | D1: =EOMONTH(C1,0) -> 44985 | F1: RESUMEN DEL FLUJO DE EFECTIVO
B2: =TEXT(DATE(Anual!$L$2,_xlfn.SHEET()-1,1),"mmmm")&" "&Anual!L2 -> febrero 2023 | J2: =H4 -> 0 | K2: Total Ingresos | R2: REGISTRO DE GASTOS
F3: CATEGORIA | G3: PRESUPUESTO | H3: REAL
B4: RESUMEN FINANCIERO | F4: Ingresos | G4: =C26 -> 0 | H4: =D26 -> 0 | J4: =SUM(H5:H9) -> 0 | K4: Total Gastos
F5: Facturas | G5: =G42 -> 0 | H5: =H42 -> 0 | R5: FECHA | S5: CATEGORIA | T5: DESCRIPCIÓN | U5: MONTO
B6: CATEGORIA | C6: PRESUPUESTO | D6: REAL | F6: Gastos | G6: =K42 -> 0 | H6: =L42 -> 0 | J6: =G10 -> 0 | K6: Saldo del presupuesto
B7: Ingresos | C7: =C26 -> 0 | D7: =D26 -> 0 | F7: Créditos | G7: =C42 -> 0 | H7: =D42 -> 0
B8: Facturas | C8: =G42 -> 0 | D8: =H42 -> 0 | F8: Ahorros | G8: =O26 -> 0 | H8: =P26 -> 0 | J8: =H10 -> 0 | K8: Saldo Real
B9: Gastos | C9: =K42 -> 0 | D9: =L42 -> 0 | F9: Inversiones | G9: =O42 -> 0 | H9: =P42 -> 0
B10: INGRESO NETO | C10: =C7-C8-C9 -> 0 | D10: =D7-D8-D9 -> 0 | F10: SALDO | G10: =G4-SUM(G5:G9) -> 0 | H10: =H4-SUM(H5:H9) -> 0 | J10: =H11 -> 0 | K10: Diferencia de Saldos
B11: DIFERENCIA | D11: =C10-D10 -> 0 | F11: DIFERENCIA | H11: =G10-H10 -> 0
B13: INGRESOS | C13: PRESUPUESTO | D13: REAL | F13: FACTURAS | G13: PRESUPUESTO | H13: REAL | J13: GASTOS | K13: PRESUPUESTO | L13: REAL | N13: AHORROS | O13: PRESUPUESTO | P13: REAL
B14: Empleo | F14: Alquiler | J14: Ropa | L14: =SUMIFS(Tabla_Gastos36[MONTO],Tabla_Gastos36[FECHA],">="&$C$1,Tabla_Gastos36[FECHA],"<="&$D$1,Tabla_Gastos36[CATEGORIA],J14) -> 0 | N14: Compra de casa
B15: Youtube | F15: Internet | J15: Restaurantes | L15: =SUMIFS(Tabla_Gastos36[MONTO],Tabla_Gastos36[FECHA],">="&$C$1,Tabla_Gastos36[FECHA],"<="&$D$1,Tabla_Gastos36[CATEGORIA],J15) -> 0 | N15: Viaje a Europa
B16: Ventas en línea | F16: Teléfono | J16: Regalos | L16: =SUMIFS(Tabla_Gastos36[MONTO],Tabla_Gastos36[FECHA],">="&$C$1,Tabla_Gastos36[FECHA],"<="&$D$1,Tabla_Gastos36[CATEGORIA],J16) -> 0 | N16: Emergencias
F17: Célular | J17: Transporte | L17: =SUMIFS(Tabla_Gastos36[MONTO],Tabla_Gastos36[FECHA],">="&$C$1,Tabla_Gastos36[FECHA],"<="&$D$1,Tabla_Gastos36[CATEGORIA],J17) -> 0
F18: Agua | J18: Entretenimiento | L18: =SUMIFS(Tabla_Gastos36[MONTO],Tabla_Gastos36[FECHA],">="&$C$1,Tabla_Gastos36[FECHA],"<="&$D$1,Tabla_Gastos36[CATEGORIA],J18) -> 0
F19: Eléctricidad | J19: Paseos | L19: =SUMIFS(Tabla_Gastos36[MONTO],Tabla_Gastos36[FECHA],">="&$C$1,Tabla_Gastos36[FECHA],"<="&$D$1,Tabla_Gastos36[CATEGORIA],J19) -> 0
F20: Gas Doméstico | J20: Médico | L20: =SUMIFS(Tabla_Gastos36[MONTO],Tabla_Gastos36[FECHA],">="&$C$1,Tabla_Gastos36[FECHA],"<="&$D$1,Tabla_Gastos36[CATEGORIA],J20) -> 0
F21: Garaje | J21: Mascotas | L21: =SUMIFS(Tabla_Gastos36[MONTO],Tabla_Gastos36[FECHA],">="&$C$1,Tabla_Gastos36[FECHA],"<="&$D$1,Tabla_Gastos36[CATEGORIA],J21) -> 0
F22: Gasolina | L22: =SUMIFS(Tabla_Gastos36[MONTO],Tabla_Gastos36[FECHA],">="&$C$1,Tabla_Gastos36[FECHA],"<="&$D$1,Tabla_Gastos36[CATEGORIA],J22) -> 0
F23: Netflix | L23: =SUMIFS(Tabla_Gastos36[MONTO],Tabla_Gastos36[FECHA],">="&$C$1,Tabla_Gastos36[FECHA],"<="&$D$1,Tabla_Gastos36[CATEGORIA],J23) -> 0
F24: Página Web | L24: =SUMIFS(Tabla_Gastos36[MONTO],Tabla_Gastos36[FECHA],">="&$C$1,Tabla_Gastos36[FECHA],"<="&$D$1,Tabla_Gastos36[CATEGORIA],J24) -> 0
L25: =SUMIFS(Tabla_Gastos36[MONTO],Tabla_Gastos36[FECHA],">="&$C$1,Tabla_Gastos36[FECHA],"<="&$D$1,Tabla_Gastos36[CATEGORIA],J25) -> 0
B26: TOTAL | C26: =SUM(C14:C25) -> 0 | D26: =SUM(D14:D25) -> 0 | L26: =SUMIFS(Tabla_Gastos36[MONTO],Tabla_Gastos36[FECHA],">="&$C$1,Tabla_Gastos36[FECHA],"<="&$D$1,Tabla_Gastos36[CATEGORIA],J26) -> 0 | N26: TOTAL | O26: =SUM(O14:O25) -> 0 | P26: =SUM(P14:P25) -> 0
B27: DIFERENCIA | D27: =C26-D26 -> 0 | N27: DIFERENCIA | P27: =O26-P26 -> 0
L28: =SUMIFS(Tabla_Gastos36[MONTO],Tabla_Gastos36[FECHA],">="&$C$1,Tabla_Gastos36[FECHA],"<="&$D$1,Tabla_Gastos36[CATEGORIA],J28) -> 0
B29: CRÉDITOS | C29: PRESUPUESTO | D29: REAL | L29: =SUMIFS(Tabla_Gastos36[MONTO],Tabla_Gastos36[FECHA],">="&$C$1,Tabla_Gastos36[FECHA],"<="&$D$1,Tabla_Gastos36[CATEGORIA],J29) -> 0 | N29: INVERSIONES | O29: PRESUPUESTO | P29: REAL
B30: Tarjeta Visa Clásica | L30: =SUMIFS(Tabla_Gastos36[MONTO],Tabla_Gastos36[FECHA],">="&$C$1,Tabla_Gastos36[FECHA],"<="&$D$1,Tabla_Gastos36[CATEGORIA],J30) -> 0 | N30: Acciones
B31: Tarjeta CRM | L31: =SUMIFS(Tabla_Gastos36[MONTO],Tabla_Gastos36[FECHA],">="&$C$1,Tabla_Gastos36[FECHA],"<="&$D$1,Tabla_Gastos36[CATEGORIA],J31) -> 0 | N31: Terrenos
B32: Préstamo personal | L32: =SUMIFS(Tabla_Gastos36[MONTO],Tabla_Gastos36[FECHA],">="&$C$1,Tabla_Gastos36[FECHA],"<="&$D$1,Tabla_Gastos36[CATEGORIA],J32) -> 0
B33: Préstamo Hipotecario | L33: =SUMIFS(Tabla_Gastos36[MONTO],Tabla_Gastos36[FECHA],">="&$C$1,Tabla_Gastos36[FECHA],"<="&$D$1,Tabla_Gastos36[CATEGORIA],J33) -> 0
L34: =SUMIFS(Tabla_Gastos36[MONTO],Tabla_Gastos36[FECHA],">="&$C$1,Tabla_Gastos36[FECHA],"<="&$D$1,Tabla_Gastos36[CATEGORIA],J34) -> 0
L35: =SUMIFS(Tabla_Gastos36[MONTO],Tabla_Gastos36[FECHA],">="&$C$1,Tabla_Gastos36[FECHA],"<="&$D$1,Tabla_Gastos36[CATEGORIA],J35) -> 0
L36: =SUMIFS(Tabla_Gastos36[MONTO],Tabla_Gastos36[FECHA],">="&$C$1,Tabla_Gastos36[FECHA],"<="&$D$1,Tabla_Gastos36[CATEGORIA],J36) -> 0
L37: =SUMIFS(Tabla_Gastos36[MONTO],Tabla_Gastos36[FECHA],">="&$C$1,Tabla_Gastos36[FECHA],"<="&$D$1,Tabla_Gastos36[CATEGORIA],J37) -> 0
L38: =SUMIFS(Tabla_Gastos36[MONTO],Tabla_Gastos36[FECHA],">="&$C$1,Tabla_Gastos36[FECHA],"<="&$D$1,Tabla_Gastos36[CATEGORIA],J38) -> 0
L39: =SUMIFS(Tabla_Gastos36[MONTO],Tabla_Gastos36[FECHA],">="&$C$1,Tabla_Gastos36[FECHA],"<="&$D$1,Tabla_Gastos36[CATEGORIA],J39) -> 0
L40: =SUMIFS(Tabla_Gastos36[MONTO],Tabla_Gastos36[FECHA],">="&$C$1,Tabla_Gastos36[FECHA],"<="&$D$1,Tabla_Gastos36[CATEGORIA],J40) -> 0
L41: =SUMIFS(Tabla_Gastos36[MONTO],Tabla_Gastos36[FECHA],">="&$C$1,Tabla_Gastos36[FECHA],"<="&$D$1,Tabla_Gastos36[CATEGORIA],J41) -> 0
...

Sheet Marzo
C1: =VALUE(B2) -> 44986 | D1: =EOMONTH(C1,0) -> 45016 | F1: RESUMEN DEL FLUJO DE EFECTIVO
B2: =TEXT(DATE(Anual!$L$2,_xlfn.SHEET()-1,1),"mmmm")&" "&Anual!L2 -> marzo 2023 | J2: =H4 -> 0 | K2: Total Ingresos | R2: REGISTRO DE GASTOS
F3: CATEGORIA | G3: PRESUPUESTO | H3: REAL
B4: RESUMEN FINANCIERO | F4: Ingresos | G4: =C26 -> 0 | H4: =D26 -> 0 | J4: =SUM(H5:H9) -> 0 | K4: Total Gastos
F5: Facturas | G5: =G42 -> 0 | H5: =H42 -> 0 | R5: FECHA | S5: CATEGORIA | T5: DESCRIPCIÓN | U5: MONTO
B6: CATEGORIA | C6: PRESUPUESTO | D6: REAL | F6: Gastos | G6: =K42 -> 0 | H6: =L42 -> 0 | J6: =G10 -> 0 | K6: Saldo del presupuesto
B7: Ingresos | C7: =C26 -> 0 | D7: =D26 -> 0 | F7: Créditos | G7: =C42 -> 0 | H7: =D42 -> 0
B8: Facturas | C8: =G42 -> 0 | D8: =H42 -> 0 | F8: Ahorros | G8: =O26 -> 0 | H8: =P26 -> 0 | J8: =H10 -> 0 | K8: Saldo Real
B9: Gastos | C9: =K42 -> 0 | D9: =L42 -> 0 | F9: Inversiones | G9: =O42 -> 0 | H9: =P42 -> 0
B10: INGRESO NETO | C10: =C7-C8-C9 -> 0 | D10: =D7-D8-D9 -> 0 | F10: SALDO | G10: =G4-SUM(G5:G9) -> 0 | H10: =H4-SUM(H5:H9) -> 0 | J10: =H11 -> 0 | K10: Diferencia de Saldos
B11: DIFERENCIA | D11: =C10-D10 -> 0 | F11: DIFERENCIA | H11: =G10-H10 -> 0
B13: INGRESOS | C13: PRESUPUESTO | D13: REAL | F13: FACTURAS | G13: PRESUPUESTO | H13: REAL | J13: GASTOS | K13: PRESUPUESTO | L13: REAL | N13: AHORROS | O13: PRESUPUESTO | P13: REAL
B14: Empleo | F14: Alquiler | J14: Ropa | L14: =SUMIFS(Tabla_Gastos367[MONTO],Tabla_Gastos367[FECHA],">="&$C$1,Tabla_Gastos367[FECHA],"<="&$D$1,Tabla_Gastos367[CATEGORIA],J14) -> 0 | N14: Compra de casa
B15: Youtube | F15: Internet | J15: Restaurantes | L15: =SUMIFS(Tabla_Gastos367[MONTO],Tabla_Gastos367[FECHA],">="&$C$1,Tabla_Gastos367[FECHA],"<="&$D$1,Tabla_Gastos367[CATEGORIA],J15) -> 0 | N15: Viaje a Europa
B16: Ventas en línea | F16: Teléfono | J16: Regalos | L16: =SUMIFS(Tabla_Gastos367[MONTO],Tabla_Gastos367[FECHA],">="&$C$1,Tabla_Gastos367[FECHA],"<="&$D$1,Tabla_Gastos367[CATEGORIA],J16) -> 0 | N16: Emergencias
F17: Célular | J17: Transporte | L17: =SUMIFS(Tabla_Gastos367[MONTO],Tabla_Gastos367[FECHA],">="&$C$1,Tabla_Gastos367[FECHA],"<="&$D$1,Tabla_Gastos367[CATEGORIA],J17) -> 0
F18: Agua | J18: Entretenimiento | L18: =SUMIFS(Tabla_Gastos367[MONTO],Tabla_Gastos367[FECHA],">="&$C$1,Tabla_Gastos367[FECHA],"<="&$D$1,Tabla_Gastos367[CATEGORIA],J18) -> 0
F19: Eléctricidad | J19: Paseos | L19: =SUMIFS(Tabla_Gastos367[MONTO],Tabla_Gastos367[FECHA],">="&$C$1,Tabla_Gastos367[FECHA],"<="&$D$1,Tabla_Gastos367[CATEGORIA],J19) -> 0
F20: Gas Doméstico | J20: Médico | L20: =SUMIFS(Tabla_Gastos367[MONTO],Tabla_Gastos367[FECHA],">="&$C$1,Tabla_Gastos367[FECHA],"<="&$D$1,Tabla_Gastos367[CATEGORIA],J20) -> 0
F21: Garaje | J21: Mascotas | L21: =SUMIFS(Tabla_Gastos367[MONTO],Tabla_Gastos367[FECHA],">="&$C$1,Tabla_Gastos367[FECHA],"<="&$D$1,Tabla_Gastos367[CATEGORIA],J21) -> 0
F22: Gasolina | L22: =SUMIFS(Tabla_Gastos367[MONTO],Tabla_Gastos367[FECHA],">="&$C$1,Tabla_Gastos367[FECHA],"<="&$D$1,Tabla_Gastos367[CATEGORIA],J22) -> 0
F23: Netflix | L23: =SUMIFS(Tabla_Gastos367[MONTO],Tabla_Gastos367[FECHA],">="&$C$1,Tabla_Gastos367[FECHA],"<="&$D$1,Tabla_Gastos367[CATEGORIA],J23) -> 0
F24: Página Web | L24: =SUMIFS(Tabla_Gastos367[MONTO],Tabla_Gastos367[FECHA],">="&$C$1,Tabla_Gastos367[FECHA],"<="&$D$1,Tabla_Gastos367[CATEGORIA],J24) -> 0
L25: =SUMIFS(Tabla_Gastos367[MONTO],Tabla_Gastos367[FECHA],">="&$C$1,Tabla_Gastos367[FECHA],"<="&$D$1,Tabla_Gastos367[CATEGORIA],J25) -> 0
B26: TOTAL | C26: =SUM(C14:C25) -> 0 | D26: =SUM(D14:D25) -> 0 | L26: =SUMIFS(Tabla_Gastos367[MONTO],Tabla_Gastos367[FECHA],">="&$C$1,Tabla_Gastos367[FECHA],"<="&$D$1,Tabla_Gastos367[CATEGORIA],J26) -> 0 | N26: TOTAL | O26: =SUM(O14:O25) -> 0 | P26: =SUM(P14:P25) -> 0
B27: DIFERENCIA | D27: =C26-D26 -> 0 | N27: DIFERENCIA | P27: =O26-P26 -> 0
L28: =SUMIFS(Tabla_Gastos367[MONTO],Tabla_Gastos367[FECHA],">="&$C$1,Tabla_Gastos367[FECHA],"<="&$D$1,Tabla_Gastos367[CATEGORIA],J28) -> 0
B29: CRÉDITOS | C29: PRESUPUESTO | D29: REAL | L29: =SUMIFS(Tabla_Gastos367[MONTO],Tabla_Gastos367[FECHA],">="&$C$1,Tabla_Gastos367[FECHA],"<="&$D$1,Tabla_Gastos367[CATEGORIA],J29) -> 0 | N29: INVERSIONES | O29: PRESUPUESTO | P29: REAL
B30: Tarjeta Visa Clásica | L30: =SUMIFS(Tabla_Gastos367[MONTO],Tabla_Gastos367[FECHA],">="&$C$1,Tabla_Gastos367[FECHA],"<="&$D$1,Tabla_Gastos367[CATEGORIA],J30) -> 0 | N30: Acciones
B31: Tarjeta CRM | L31: =SUMIFS(Tabla_Gastos367[MONTO],Tabla_Gastos367[FECHA],">="&$C$1,Tabla_Gastos367[FECHA],"<="&$D$1,Tabla_Gastos367[CATEGORIA],J31) -> 0 | N31: Terrenos
B32: Préstamo personal | L32: =SUMIFS(Tabla_Gastos367[MONTO],Tabla_Gastos367[FECHA],">="&$C$1,Tabla_Gastos367[FECHA],"<="&$D$1,Tabla_Gastos367[CATEGORIA],J32) -> 0
B33: Préstamo Hipotecario | L33: =SUMIFS(Tabla_Gastos367[MONTO],Tabla_Gastos367[FECHA],">="&$C$1,Tabla_Gastos367[FECHA],"<="&$D$1,Tabla_Gastos367[CATEGORIA],J33) -> 0
L34: =SUMIFS(Tabla_Gastos367[MONTO],Tabla_Gastos367[FECHA],">="&$C$1,Tabla_Gastos367[FECHA],"<="&$D$1,Tabla_Gastos367[CATEGORIA],J34) -> 0
L35: =SUMIFS(Tabla_Gastos367[MONTO],Tabla_Gastos367[FECHA],">="&$C$1,Tabla_Gastos367[FECHA],"<="&$D$1,Tabla_Gastos367[CATEGORIA],J35) -> 0
L36: =SUMIFS(Tabla_Gastos367[MONTO],Tabla_Gastos367[FECHA],">="&$C$1,Tabla_Gastos367[FECHA],"<="&$D$1,Tabla_Gastos367[CATEGORIA],J36) -> 0
L37: =SUMIFS(Tabla_Gastos367[MONTO],Tabla_Gastos367[FECHA],">="&$C$1,Tabla_Gastos367[FECHA],"<="&$D$1,Tabla_Gastos367[CATEGORIA],J37) -> 0
L38: =SUMIFS(Tabla_Gastos367[MONTO],Tabla_Gastos367[FECHA],">="&$C$1,Tabla_Gastos367[FECHA],"<="&$D$1,Tabla_Gastos367[CATEGORIA],J38) -> 0
L39: =SUMIFS(Tabla_Gastos367[MONTO],Tabla_Gastos367[FECHA],">="&$C$1,Tabla_Gastos367[FECHA],"<="&$D$1,Tabla_Gastos367[CATEGORIA],J39) -> 0
L40: =SUMIFS(Tabla_Gastos367[MONTO],Tabla_Gastos367[FECHA],">="&$C$1,Tabla_Gastos367[FECHA],"<="&$D$1,Tabla_Gastos367[CATEGORIA],J40) -> 0
L41: =SUMIFS(Tabla_Gastos367[MONTO],Tabla_Gastos367[FECHA],">="&$C$1,Tabla_Gastos367[FECHA],"<="&$D$1,Tabla_Gastos367[CATEGORIA],J41) -> 0
...

Sheet Abril
C1: =VALUE(B2) -> 45017 | D1: =EOMONTH(C1,0) -> 45046 | F1: RESUMEN DEL FLUJO DE EFECTIVO
B2: =TEXT(DATE(Anual!$L$2,_xlfn.SHEET()-1,1),"mmmm")&" "&Anual!L2 -> abril 2023 | J2: =H4 -> 0 | K2: Total Ingresos | R2: REGISTRO DE GASTOS
F3: CATEGORIA | G3: PRESUPUESTO | H3: REAL
B4: RESUMEN FINANCIERO | F4: Ingresos | G4: =C26 -> 0 | H4: =D26 -> 0 | J4: =SUM(H5:H9) -> 0 | K4: Total Gastos
F5: Facturas | G5: =G42 -> 0 | H5: =H42 -> 0 | R5: FECHA | S5: CATEGORIA | T5: DESCRIPCIÓN | U5: MONTO
B6: CATEGORIA | C6: PRESUPUESTO | D6: REAL | F6: Gastos | G6: =K42 -> 0 | H6: =L42 -> 0 | J6: =G10 -> 0 | K6: Saldo del presupuesto
B7: Ingresos | C7: =C26 -> 0 | D7: =D26 -> 0 | F7: Créditos | G7: =C42 -> 0 | H7: =D42 -> 0
B8: Facturas | C8: =G42 -> 0 | D8: =H42 -> 0 | F8: Ahorros | G8: =O26 -> 0 | H8: =P26 -> 0 | J8: =H10 -> 0 | K8: Saldo Real
B9: Gastos | C9: =K42 -> 0 | D9: =L42 -> 0 | F9: Inversiones | G9: =O42 -> 0 | H9: =P42 -> 0
B10: INGRESO NETO | C10: =C7-C8-C9 -> 0 | D10: =D7-D8-D9 -> 0 | F10: SALDO | G10: =G4-SUM(G5:G9) -> 0 | H10: =H4-SUM(H5:H9) -> 0 | J10: =H11 -> 0 | K10: Diferencia de Saldos
B11: DIFERENCIA | D11: =C10-D10 -> 0 | F11: DIFERENCIA | H11: =G10-H10 -> 0
B13: INGRESOS | C13: PRESUPUESTO | D13: REAL | F13: FACTURAS | G13: PRESUPUESTO | H13: REAL | J13: GASTOS | K13: PRESUPUESTO | L13: REAL | N13: AHORROS | O13: PRESUPUESTO | P13: REAL
B14: Empleo | F14: Alquiler | J14: Ropa | L14: =SUMIFS(Tabla_Gastos3678[MONTO],Tabla_Gastos3678[FECHA],">="&$C$1,Tabla_Gastos3678[FECHA],"<="&$D$1,Tabla_Gastos3678[CATEGORIA],J14) -> 0 | N14: Compra de casa
B15: Youtube | F15: Internet | J15: Restaurantes | L15: =SUMIFS(Tabla_Gastos3678[MONTO],Tabla_Gastos3678[FECHA],">="&$C$1,Tabla_Gastos3678[FECHA],"<="&$D$1,Tabla_Gastos3678[CATEGORIA],J15) -> 0 | N15: Viaje a Europa
B16: Ventas en línea | F16: Teléfono | J16: Regalos | L16: =SUMIFS(Tabla_Gastos3678[MONTO],Tabla_Gastos3678[FECHA],">="&$C$1,Tabla_Gastos3678[FECHA],"<="&$D$1,Tabla_Gastos3678[CATEGORIA],J16) -> 0 | N16: Emergencias
F17: Célular | J17: Transporte | L17: =SUMIFS(Tabla_Gastos3678[MONTO],Tabla_Gastos3678[FECHA],">="&$C$1,Tabla_Gastos3678[FECHA],"<="&$D$1,Tabla_Gastos3678[CATEGORIA],J17) -> 0
F18: Agua | J18: Entretenimiento | L18: =SUMIFS(Tabla_Gastos3678[MONTO],Tabla_Gastos3678[FECHA],">="&$C$1,Tabla_Gastos3678[FECHA],"<="&$D$1,Tabla_Gastos3678[CATEGORIA],J18) -> 0
F19: Eléctricidad | J19: Paseos | L19: =SUMIFS(Tabla_Gastos3678[MONTO],Tabla_Gastos3678[FECHA],">="&$C$1,Tabla_Gastos3678[FECHA],"<="&$D$1,Tabla_Gastos3678[CATEGORIA],J19) -> 0
F20: Gas Doméstico | J20: Médico | L20: =SUMIFS(Tabla_Gastos3678[MONTO],Tabla_Gastos3678[FECHA],">="&$C$1,Tabla_Gastos3678[FECHA],"<="&$D$1,Tabla_Gastos3678[CATEGORIA],J20) -> 0
F21: Garaje | J21: Mascotas | L21: =SUMIFS(Tabla_Gastos3678[MONTO],Tabla_Gastos3678[FECHA],">="&$C$1,Tabla_Gastos3678[FECHA],"<="&$D$1,Tabla_Gastos3678[CATEGORIA],J21) -> 0
F22: Gasolina | L22: =SUMIFS(Tabla_Gastos3678[MONTO],Tabla_Gastos3678[FECHA],">="&$C$1,Tabla_Gastos3678[FECHA],"<="&$D$1,Tabla_Gastos3678[CATEGORIA],J22) -> 0
F23: Netflix | L23: =SUMIFS(Tabla_Gastos3678[MONTO],Tabla_Gastos3678[FECHA],">="&$C$1,Tabla_Gastos3678[FECHA],"<="&$D$1,Tabla_Gastos3678[CATEGORIA],J23) -> 0
F24: Página Web | L24: =SUMIFS(Tabla_Gastos3678[MONTO],Tabla_Gastos3678[FECHA],">="&$C$1,Tabla_Gastos3678[FECHA],"<="&$D$1,Tabla_Gastos3678[CATEGORIA],J24) -> 0
L25: =SUMIFS(Tabla_Gastos3678[MONTO],Tabla_Gastos3678[FECHA],">="&$C$1,Tabla_Gastos3678[FECHA],"<="&$D$1,Tabla_Gastos3678[CATEGORIA],J25) -> 0
B26: TOTAL | C26: =SUM(C14:C25) -> 0 | D26: =SUM(D14:D25) -> 0 | L26: =SUMIFS(Tabla_Gastos3678[MONTO],Tabla_Gastos3678[FECHA],">="&$C$1,Tabla_Gastos3678[FECHA],"<="&$D$1,Tabla_Gastos3678[CATEGORIA],J26) -> 0 | N26: TOTAL | O26: =SUM(O14:O25) -> 0 | P26: =SUM(P14:P25) -> 0
B27: DIFERENCIA | D27: =C26-D26 -> 0 | N27: DIFERENCIA | P27: =O26-P26 -> 0
L28: =SUMIFS(Tabla_Gastos3678[MONTO],Tabla_Gastos3678[FECHA],">="&$C$1,Tabla_Gastos3678[FECHA],"<="&$D$1,Tabla_Gastos3678[CATEGORIA],J28) -> 0
B29: CRÉDITOS | C29: PRESUPUESTO | D29: REAL | L29: =SUMIFS(Tabla_Gastos3678[MONTO],Tabla_Gastos3678[FECHA],">="&$C$1,Tabla_Gastos3678[FECHA],"<="&$D$1,Tabla_Gastos3678[CATEGORIA],J29) -> 0 | N29: INVERSIONES | O29: PRESUPUESTO | P29: REAL
B30: Tarjeta Visa Clásica | L30: =SUMIFS(Tabla_Gastos3678[MONTO],Tabla_Gastos3678[FECHA],">="&$C$1,Tabla_Gastos3678[FECHA],"<="&$D$1,Tabla_Gastos3678[CATEGORIA],J30) -> 0 | N30: Acciones
B31: Tarjeta CRM | L31: =SUMIFS(Tabla_Gastos3678[MONTO],Tabla_Gastos3678[FECHA],">="&$C$1,Tabla_Gastos3678[FECHA],"<="&$D$1,Tabla_Gastos3678[CATEGORIA],J31) -> 0 | N31: Terrenos
B32: Préstamo personal | L32: =SUMIFS(Tabla_Gastos3678[MONTO],Tabla_Gastos3678[FECHA],">="&$C$1,Tabla_Gastos3678[FECHA],"<="&$D$1,Tabla_Gastos3678[CATEGORIA],J32) -> 0
B33: Préstamo Hipotecario | L33: =SUMIFS(Tabla_Gastos3678[MONTO],Tabla_Gastos3678[FECHA],">="&$C$1,Tabla_Gastos3678[FECHA],"<="&$D$1,Tabla_Gastos3678[CATEGORIA],J33) -> 0
L34: =SUMIFS(Tabla_Gastos3678[MONTO],Tabla_Gastos3678[FECHA],">="&$C$1,Tabla_Gastos3678[FECHA],"<="&$D$1,Tabla_Gastos3678[CATEGORIA],J34) -> 0
L35: =SUMIFS(Tabla_Gastos3678[MONTO],Tabla_Gastos3678[FECHA],">="&$C$1,Tabla_Gastos3678[FECHA],"<="&$D$1,Tabla_Gastos3678[CATEGORIA],J35) -> 0
L36: =SUMIFS(Tabla_Gastos3678[MONTO],Tabla_Gastos3678[FECHA],">="&$C$1,Tabla_Gastos3678[FECHA],"<="&$D$1,Tabla_Gastos3678[CATEGORIA],J36) -> 0
L37: =SUMIFS(Tabla_Gastos3678[MONTO],Tabla_Gastos3678[FECHA],">="&$C$1,Tabla_Gastos3678[FECHA],"<="&$D$1,Tabla_Gastos3678[CATEGORIA],J37) -> 0
L38: =SUMIFS(Tabla_Gastos3678[MONTO],Tabla_Gastos3678[FECHA],">="&$C$1,Tabla_Gastos3678[FECHA],"<="&$D$1,Tabla_Gastos3678[CATEGORIA],J38) -> 0
L39: =SUMIFS(Tabla_Gastos3678[MONTO],Tabla_Gastos3678[FECHA],">="&$C$1,Tabla_Gastos3678[FECHA],"<="&$D$1,Tabla_Gastos3678[CATEGORIA],J39) -> 0
L40: =SUMIFS(Tabla_Gastos3678[MONTO],Tabla_Gastos3678[FECHA],">="&$C$1,Tabla_Gastos3678[FECHA],"<="&$D$1,Tabla_Gastos3678[CATEGORIA],J40) -> 0
L41: =SUMIFS(Tabla_Gastos3678[MONTO],Tabla_Gastos3678[FECHA],">="&$C$1,Tabla_Gastos3678[FECHA],"<="&$D$1,Tabla_Gastos3678[CATEGORIA],J41) -> 0
...

Sheet Mayo
C1: =VALUE(B2) -> 45047 | D1: =EOMONTH(C1,0) -> 45077 | F1: RESUMEN DEL FLUJO DE EFECTIVO
B2: =TEXT(DATE(Anual!$L$2,_xlfn.SHEET()-1,1),"mmmm")&" "&Anual!L2 -> mayo 2023 | J2: =H4 -> 0 | K2: Total Ingresos | R2: REGISTRO DE GASTOS
F3: CATEGORIA | G3: PRESUPUESTO | H3: REAL
B4: RESUMEN FINANCIERO | F4: Ingresos | G4: =C26 -> 0 | H4: =D26 -> 0 | J4: =SUM(H5:H9) -> 0 | K4: Total Gastos
F5: Facturas | G5: =G42 -> 0 | H5: =H42 -> 0 | R5: FECHA | S5: CATEGORIA | T5: DESCRIPCIÓN | U5: MONTO
B6: CATEGORIA | C6: PRESUPUESTO | D6: REAL | F6: Gastos | G6: =K42 -> 0 | H6: =L42 -> 0 | J6: =G10 -> 0 | K6: Saldo del presupuesto
B7: Ingresos | C7: =C26 -> 0 | D7: =D26 -> 0 | F7: Créditos | G7: =C42 -> 0 | H7: =D42 -> 0
B8: Facturas | C8: =G42 -> 0 | D8: =H42 -> 0 | F8: Ahorros | G8: =O26 -> 0 | H8: =P26 -> 0 | J8: =H10 -> 0 | K8: Saldo Real
B9: Gastos | C9: =K42 -> 0 | D9: =L42 -> 0 | F9: Inversiones | G9: =O42 -> 0 | H9: =P42 -> 0
B10: INGRESO NETO | C10: =C7-C8-C9 -> 0 | D10: =D7-D8-D9 -> 0 | F10: SALDO | G10: =G4-SUM(G5:G9) -> 0 | H10: =H4-SUM(H5:H9) -> 0 | J10: =H11 -> 0 | K10: Diferencia de Saldos
B11: DIFERENCIA | D11: =C10-D10 -> 0 | F11: DIFERENCIA | H11: =G10-H10 -> 0
B13: INGRESOS | C13: PRESUPUESTO | D13: REAL | F13: FACTURAS | G13: PRESUPUESTO | H13: REAL | J13: GASTOS | K13: PRESUPUESTO | L13: REAL | N13: AHORROS | O13: PRESUPUESTO | P13: REAL
B14: Empleo | F14: Alquiler | J14: Ropa | L14: =SUMIFS(Tabla_Gastos36789[MONTO],Tabla_Gastos36789[FECHA],">="&$C$1,Tabla_Gastos36789[FECHA],"<="&$D$1,Tabla_Gastos36789[CATEGORIA],J14) -> 0 | N14: Compra de casa
B15: Youtube | F15: Internet | J15: Restaurantes | L15: =SUMIFS(Tabla_Gastos36789[MONTO],Tabla_Gastos36789[FECHA],">="&$C$1,Tabla_Gastos36789[FECHA],"<="&$D$1,Tabla_Gastos36789[CATEGORIA],J15) -> 0 | N15: Viaje a Europa
B16: Ventas en línea | F16: Teléfono | J16: Regalos | L16: =SUMIFS(Tabla_Gastos36789[MONTO],Tabla_Gastos36789[FECHA],">="&$C$1,Tabla_Gastos36789[FECHA],"<="&$D$1,Tabla_Gastos36789[CATEGORIA],J16) -> 0 | N16: Emergencias
F17: Célular | J17: Transporte | L17: =SUMIFS(Tabla_Gastos36789[MONTO],Tabla_Gastos36789[FECHA],">="&$C$1,Tabla_Gastos36789[FECHA],"<="&$D$1,Tabla_Gastos36789[CATEGORIA],J17) -> 0
F18: Agua | J18: Entretenimiento | L18: =SUMIFS(Tabla_Gastos36789[MONTO],Tabla_Gastos36789[FECHA],">="&$C$1,Tabla_Gastos36789[FECHA],"<="&$D$1,Tabla_Gastos36789[CATEGORIA],J18) -> 0
F19: Eléctricidad | J19: Paseos | L19: =SUMIFS(Tabla_Gastos36789[MONTO],Tabla_Gastos36789[FECHA],">="&$C$1,Tabla_Gastos36789[FECHA],"<="&$D$1,Tabla_Gastos36789[CATEGORIA],J19) -> 0
F20: Gas Doméstico | J20: Médico | L20: =SUMIFS(Tabla_Gastos36789[MONTO],Tabla_Gastos36789[FECHA],">="&$C$1,Tabla_Gastos36789[FECHA],"<="&$D$1,Tabla_Gastos36789[CATEGORIA],J20) -> 0
F21: Garaje | J21: Mascotas | L21: =SUMIFS(Tabla_Gastos36789[MONTO],Tabla_Gastos36789[FECHA],">="&$C$1,Tabla_Gastos36789[FECHA],"<="&$D$1,Tabla_Gastos36789[CATEGORIA],J21) -> 0
F22: Gasolina | L22: =SUMIFS(Tabla_Gastos36789[MONTO],Tabla_Gastos36789[FECHA],">="&$C$1,Tabla_Gastos36789[FECHA],"<="&$D$1,Tabla_Gastos36789[CATEGORIA],J22) -> 0
F23: Netflix | L23: =SUMIFS(Tabla_Gastos36789[MONTO],Tabla_Gastos36789[FECHA],">="&$C$1,Tabla_Gastos36789[FECHA],"<="&$D$1,Tabla_Gastos36789[CATEGORIA],J23) -> 0
F24: Página Web | L24: =SUMIFS(Tabla_Gastos36789[MONTO],Tabla_Gastos36789[FECHA],">="&$C$1,Tabla_Gastos36789[FECHA],"<="&$D$1,Tabla_Gastos36789[CATEGORIA],J24) -> 0
L25: =SUMIFS(Tabla_Gastos36789[MONTO],Tabla_Gastos36789[FECHA],">="&$C$1,Tabla_Gastos36789[FECHA],"<="&$D$1,Tabla_Gastos36789[CATEGORIA],J25) -> 0
B26: TOTAL | C26: =SUM(C14:C25) -> 0 | D26: =SUM(D14:D25) -> 0 | L26: =SUMIFS(Tabla_Gastos36789[MONTO],Tabla_Gastos36789[FECHA],">="&$C$1,Tabla_Gastos36789[FECHA],"<="&$D$1,Tabla_Gastos36789[CATEGORIA],J26) -> 0 | N26: TOTAL | O26: =SUM(O14:O25) -> 0 | P26: =SUM(P14:P25) -> 0
B27: DIFERENCIA | D27: =C26-D26 -> 0 | N27: DIFERENCIA | P27: =O26-P26 -> 0
L28: =SUMIFS(Tabla_Gastos36789[MONTO],Tabla_Gastos36789[FECHA],">="&$C$1,Tabla_Gastos36789[FECHA],"<="&$D$1,Tabla_Gastos36789[CATEGORIA],J28) -> 0
B29: CRÉDITOS | C29: PRESUPUESTO | D29: REAL | L29: =SUMIFS(Tabla_Gastos36789[MONTO],Tabla_Gastos36789[FECHA],">="&$C$1,Tabla_Gastos36789[FECHA],"<="&$D$1,Tabla_Gastos36789[CATEGORIA],J29) -> 0 | N29: INVERSIONES | O29: PRESUPUESTO | P29: REAL
B30: Tarjeta Visa Clásica | L30: =SUMIFS(Tabla_Gastos36789[MONTO],Tabla_Gastos36789[FECHA],">="&$C$1,Tabla_Gastos36789[FECHA],"<="&$D$1,Tabla_Gastos36789[CATEGORIA],J30) -> 0 | N30: Acciones
B31: Tarjeta CRM | L31: =SUMIFS(Tabla_Gastos36789[MONTO],Tabla_Gastos36789[FECHA],">="&$C$1,Tabla_Gastos36789[FECHA],"<="&$D$1,Tabla_Gastos36789[CATEGORIA],J31) -> 0 | N31: Terrenos
B32: Préstamo personal | L32: =SUMIFS(Tabla_Gastos36789[MONTO],Tabla_Gastos36789[FECHA],">="&$C$1,Tabla_Gastos36789[FECHA],"<="&$D$1,Tabla_Gastos36789[CATEGORIA],J32) -> 0
B33: Préstamo Hipotecario | L33: =SUMIFS(Tabla_Gastos36789[MONTO],Tabla_Gastos36789[FECHA],">="&$C$1,Tabla_Gastos36789[FECHA],"<="&$D$1,Tabla_Gastos36789[CATEGORIA],J33) -> 0
L34: =SUMIFS(Tabla_Gastos36789[MONTO],Tabla_Gastos36789[FECHA],">="&$C$1,Tabla_Gastos36789[FECHA],"<="&$D$1,Tabla_Gastos36789[CATEGORIA],J34) -> 0
L35: =SUMIFS(Tabla_Gastos36789[MONTO],Tabla_Gastos36789[FECHA],">="&$C$1,Tabla_Gastos36789[FECHA],"<="&$D$1,Tabla_Gastos36789[CATEGORIA],J35) -> 0
L36: =SUMIFS(Tabla_Gastos36789[MONTO],Tabla_Gastos36789[FECHA],">="&$C$1,Tabla_Gastos36789[FECHA],"<="&$D$1,Tabla_Gastos36789[CATEGORIA],J36) -> 0
L37: =SUMIFS(Tabla_Gastos36789[MONTO],Tabla_Gastos36789[FECHA],">="&$C$1,Tabla_Gastos36789[FECHA],"<="&$D$1,Tabla_Gastos36789[CATEGORIA],J37) -> 0
L38: =SUMIFS(Tabla_Gastos36789[MONTO],Tabla_Gastos36789[FECHA],">="&$C$1,Tabla_Gastos36789[FECHA],"<="&$D$1,Tabla_Gastos36789[CATEGORIA],J38) -> 0
L39: =SUMIFS(Tabla_Gastos36789[MONTO],Tabla_Gastos36789[FECHA],">="&$C$1,Tabla_Gastos36789[FECHA],"<="&$D$1,Tabla_Gastos36789[CATEGORIA],J39) -> 0
L40: =SUMIFS(Tabla_Gastos36789[MONTO],Tabla_Gastos36789[FECHA],">="&$C$1,Tabla_Gastos36789[FECHA],"<="&$D$1,Tabla_Gastos36789[CATEGORIA],J40) -> 0
L41: =SUMIFS(Tabla_Gastos36789[MONTO],Tabla_Gastos36789[FECHA],">="&$C$1,Tabla_Gastos36789[FECHA],"<="&$D$1,Tabla_Gastos36789[CATEGORIA],J41) -> 0
...

Sheet Junio
C1: =VALUE(B2) -> 45078 | D1: =EOMONTH(C1,0) -> 45107 | F1: RESUMEN DEL FLUJO DE EFECTIVO
B2: =TEXT(DATE(Anual!$L$2,_xlfn.SHEET()-1,1),"mmmm")&" "&Anual!L2 -> junio 2023 | J2: =H4 -> 0 | K2: Total Ingresos | R2: REGISTRO DE GASTOS
F3: CATEGORIA | G3: PRESUPUESTO | H3: REAL
B4: RESUMEN FINANCIERO | F4: Ingresos | G4: =C26 -> 0 | H4: =D26 -> 0 | J4: =SUM(H5:H9) -> 0 | K4: Total Gastos
F5: Facturas | G5: =G42 -> 0 | H5: =H42 -> 0 | R5: FECHA | S5: CATEGORIA | T5: DESCRIPCIÓN | U5: MONTO
B6: CATEGORIA | C6: PRESUPUESTO | D6: REAL | F6: Gastos | G6: =K42 -> 0 | H6: =L42 -> 0 | J6: =G10 -> 0 | K6: Saldo del presupuesto
B7: Ingresos | C7: =C26 -> 0 | D7: =D26 -> 0 | F7: Créditos | G7: =C42 -> 0 | H7: =D42 -> 0
B8: Facturas | C8: =G42 -> 0 | D8: =H42 -> 0 | F8: Ahorros | G8: =O26 -> 0 | H8: =P26 -> 0 | J8: =H10 -> 0 | K8: Saldo Real
B9: Gastos | C9: =K42 -> 0 | D9: =L42 -> 0 | F9: Inversiones | G9: =O42 -> 0 | H9: =P42 -> 0
B10: INGRESO NETO | C10: =C7-C8-C9 -> 0 | D10: =D7-D8-D9 -> 0 | F10: SALDO | G10: =G4-SUM(G5:G9) -> 0 | H10: =H4-SUM(H5:H9) -> 0 | J10: =H11 -> 0 | K10: Diferencia de Saldos
B11: DIFERENCIA | D11: =C10-D10 -> 0 | F11: DIFERENCIA | H11: =G10-H10 -> 0
B13: INGRESOS | C13: PRESUPUESTO | D13: REAL | F13: FACTURAS | G13: PRESUPUESTO | H13: REAL | J13: GASTOS | K13: PRESUPUESTO | L13: REAL | N13: AHORROS | O13: PRESUPUESTO | P13: REAL
B14: Empleo | F14: Alquiler | J14: Ropa | L14: =SUMIFS(Tabla_Gastos3678910[MONTO],Tabla_Gastos3678910[FECHA],">="&$C$1,Tabla_Gastos3678910[FECHA],"<="&$D$1,Tabla_Gastos3678910[CATEGORIA],J14) -> 0 | N14: Compra de casa
B15: Youtube | F15: Internet | J15: Restaurantes | L15: =SUMIFS(Tabla_Gastos3678910[MONTO],Tabla_Gastos3678910[FECHA],">="&$C$1,Tabla_Gastos3678910[FECHA],"<="&$D$1,Tabla_Gastos3678910[CATEGORIA],J15) -> 0 | N15: Viaje a Europa
B16: Ventas en línea | F16: Teléfono | J16: Regalos | L16: =SUMIFS(Tabla_Gastos3678910[MONTO],Tabla_Gastos3678910[FECHA],">="&$C$1,Tabla_Gastos3678910[FECHA],"<="&$D$1,Tabla_Gastos3678910[CATEGORIA],J16) -> 0 | N16: Emergencias
F17: Célular | J17: Transporte | L17: =SUMIFS(Tabla_Gastos3678910[MONTO],Tabla_Gastos3678910[FECHA],">="&$C$1,Tabla_Gastos3678910[FECHA],"<="&$D$1,Tabla_Gastos3678910[CATEGORIA],J17) -> 0
F18: Agua | J18: Entretenimiento | L18: =SUMIFS(Tabla_Gastos3678910[MONTO],Tabla_Gastos3678910[FECHA],">="&$C$1,Tabla_Gastos3678910[FECHA],"<="&$D$1,Tabla_Gastos3678910[CATEGORIA],J18) -> 0
F19: Eléctricidad | J19: Paseos | L19: =SUMIFS(Tabla_Gastos3678910[MONTO],Tabla_Gastos3678910[FECHA],">="&$C$1,Tabla_Gastos3678910[FECHA],"<="&$D$1,Tabla_Gastos3678910[CATEGORIA],J19) -> 0
F20: Gas Doméstico | J20: Médico | L20: =SUMIFS(Tabla_Gastos3678910[MONTO],Tabla_Gastos3678910[FECHA],">="&$C$1,Tabla_Gastos3678910[FECHA],"<="&$D$1,Tabla_Gastos3678910[CATEGORIA],J20) -> 0
F21: Garaje | J21: Mascotas | L21: =SUMIFS(Tabla_Gastos3678910[MONTO],Tabla_Gastos3678910[FECHA],">="&$C$1,Tabla_Gastos3678910[FECHA],"<="&$D$1,Tabla_Gastos3678910[CATEGORIA],J21) -> 0
F22: Gasolina | L22: =SUMIFS(Tabla_Gastos3678910[MONTO],Tabla_Gastos3678910[FECHA],">="&$C$1,Tabla_Gastos3678910[FECHA],"<="&$D$1,Tabla_Gastos3678910[CATEGORIA],J22) -> 0
F23: Netflix | L23: =SUMIFS(Tabla_Gastos3678910[MONTO],Tabla_Gastos3678910[FECHA],">="&$C$1,Tabla_Gastos3678910[FECHA],"<="&$D$1,Tabla_Gastos3678910[CATEGORIA],J23) -> 0
F24: Página Web | L24: =SUMIFS(Tabla_Gastos3678910[MONTO],Tabla_Gastos3678910[FECHA],">="&$C$1,Tabla_Gastos3678910[FECHA],"<="&$D$1,Tabla_Gastos3678910[CATEGORIA],J24) -> 0
L25: =SUMIFS(Tabla_Gastos3678910[MONTO],Tabla_Gastos3678910[FECHA],">="&$C$1,Tabla_Gastos3678910[FECHA],"<="&$D$1,Tabla_Gastos3678910[CATEGORIA],J25) -> 0
B26: TOTAL | C26: =SUM(C14:C25) -> 0 | D26: =SUM(D14:D25) -> 0 | L26: =SUMIFS(Tabla_Gastos3678910[MONTO],Tabla_Gastos3678910[FECHA],">="&$C$1,Tabla_Gastos3678910[FECHA],"<="&$D$1,Tabla_Gastos3678910[CATEGORIA],J26) -> 0 | N26: TOTAL | O26: =SUM(O14:O25) -> 0 | P26: =SUM(P14:P25) -> 0
B27: DIFERENCIA | D27: =C26-D26 -> 0 | N27: DIFERENCIA | P27: =O26-P26 -> 0
L28: =SUMIFS(Tabla_Gastos3678910[MONTO],Tabla_Gastos3678910[FECHA],">="&$C$1,Tabla_Gastos3678910[FECHA],"<="&$D$1,Tabla_Gastos3678910[CATEGORIA],J28) -> 0
B29: CRÉDITOS | C29: PRESUPUESTO | D29: REAL | L29: =SUMIFS(Tabla_Gastos3678910[MONTO],Tabla_Gastos3678910[FECHA],">="&$C$1,Tabla_Gastos3678910[FECHA],"<="&$D$1,Tabla_Gastos3678910[CATEGORIA],J29) -> 0 | N29: INVERSIONES | O29: PRESUPUESTO | P29: REAL
B30: Tarjeta Visa Clásica | L30: =SUMIFS(Tabla_Gastos3678910[MONTO],Tabla_Gastos3678910[FECHA],">="&$C$1,Tabla_Gastos3678910[FECHA],"<="&$D$1,Tabla_Gastos3678910[CATEGORIA],J30) -> 0 | N30: Acciones
B31: Tarjeta CRM | L31: =SUMIFS(Tabla_Gastos3678910[MONTO],Tabla_Gastos3678910[FECHA],">="&$C$1,Tabla_Gastos3678910[FECHA],"<="&$D$1,Tabla_Gastos3678910[CATEGORIA],J31) -> 0 | N31: Terrenos
B32: Préstamo personal | L32: =SUMIFS(Tabla_Gastos3678910[MONTO],Tabla_Gastos3678910[FECHA],">="&$C$1,Tabla_Gastos3678910[FECHA],"<="&$D$1,Tabla_Gastos3678910[CATEGORIA],J32) -> 0
B33: Préstamo Hipotecario | L33: =SUMIFS(Tabla_Gastos3678910[MONTO],Tabla_Gastos3678910[FECHA],">="&$C$1,Tabla_Gastos3678910[FECHA],"<="&$D$1,Tabla_Gastos3678910[CATEGORIA],J33) -> 0
L34: =SUMIFS(Tabla_Gastos3678910[MONTO],Tabla_Gastos3678910[FECHA],">="&$C$1,Tabla_Gastos3678910[FECHA],"<="&$D$1,Tabla_Gastos3678910[CATEGORIA],J34) -> 0
L35: =SUMIFS(Tabla_Gastos3678910[MONTO],Tabla_Gastos3678910[FECHA],">="&$C$1,Tabla_Gastos3678910[FECHA],"<="&$D$1,Tabla_Gastos3678910[CATEGORIA],J35) -> 0
L36: =SUMIFS(Tabla_Gastos3678910[MONTO],Tabla_Gastos3678910[FECHA],">="&$C$1,Tabla_Gastos3678910[FECHA],"<="&$D$1,Tabla_Gastos3678910[CATEGORIA],J36) -> 0
L37: =SUMIFS(Tabla_Gastos3678910[MONTO],Tabla_Gastos3678910[FECHA],">="&$C$1,Tabla_Gastos3678910[FECHA],"<="&$D$1,Tabla_Gastos3678910[CATEGORIA],J37) -> 0
L38: =SUMIFS(Tabla_Gastos3678910[MONTO],Tabla_Gastos3678910[FECHA],">="&$C$1,Tabla_Gastos3678910[FECHA],"<="&$D$1,Tabla_Gastos3678910[CATEGORIA],J38) -> 0
L39: =SUMIFS(Tabla_Gastos3678910[MONTO],Tabla_Gastos3678910[FECHA],">="&$C$1,Tabla_Gastos3678910[FECHA],"<="&$D$1,Tabla_Gastos3678910[CATEGORIA],J39) -> 0
L40: =SUMIFS(Tabla_Gastos3678910[MONTO],Tabla_Gastos3678910[FECHA],">="&$C$1,Tabla_Gastos3678910[FECHA],"<="&$D$1,Tabla_Gastos3678910[CATEGORIA],J40) -> 0
L41: =SUMIFS(Tabla_Gastos3678910[MONTO],Tabla_Gastos3678910[FECHA],">="&$C$1,Tabla_Gastos3678910[FECHA],"<="&$D$1,Tabla_Gastos3678910[CATEGORIA],J41) -> 0
...

Sheet Julio
C1: =VALUE(B2) -> 45108 | D1: =EOMONTH(C1,0) -> 45138 | F1: RESUMEN DEL FLUJO DE EFECTIVO
B2: =TEXT(DATE(Anual!$L$2,_xlfn.SHEET()-1,1),"mmmm")&" "&Anual!L2 -> julio 2023 | J2: =H4 -> 0 | K2: Total Ingresos | R2: REGISTRO DE GASTOS
F3: CATEGORIA | G3: PRESUPUESTO | H3: REAL
B4: RESUMEN FINANCIERO | F4: Ingresos | G4: =C26 -> 0 | H4: =D26 -> 0 | J4: =SUM(H5:H9) -> 0 | K4: Total Gastos
F5: Facturas | G5: =G42 -> 0 | H5: =H42 -> 0 | R5: FECHA | S5: CATEGORIA | T5: DESCRIPCIÓN | U5: MONTO
B6: CATEGORIA | C6: PRESUPUESTO | D6: REAL | F6: Gastos | G6: =K42 -> 0 | H6: =L42 -> 0 | J6: =G10 -> 0 | K6: Saldo del presupuesto
B7: Ingresos | C7: =C26 -> 0 | D7: =D26 -> 0 | F7: Créditos | G7: =C42 -> 0 | H7: =D42 -> 0
B8: Facturas | C8: =G42 -> 0 | D8: =H42 -> 0 | F8: Ahorros | G8: =O26 -> 0 | H8: =P26 -> 0 | J8: =H10 -> 0 | K8: Saldo Real
B9: Gastos | C9: =K42 -> 0 | D9: =L42 -> 0 | F9: Inversiones | G9: =O42 -> 0 | H9: =P42 -> 0
B10: INGRESO NETO | C10: =C7-C8-C9 -> 0 | D10: =D7-D8-D9 -> 0 | F10: SALDO | G10: =G4-SUM(G5:G9) -> 0 | H10: =H4-SUM(H5:H9) -> 0 | J10: =H11 -> 0 | K10: Diferencia de Saldos
B11: DIFERENCIA | D11: =C10-D10 -> 0 | F11: DIFERENCIA | H11: =G10-H10 -> 0
B13: INGRESOS | C13: PRESUPUESTO | D13: REAL | F13: FACTURAS | G13: PRESUPUESTO | H13: REAL | J13: GASTOS | K13: PRESUPUESTO | L13: REAL | N13: AHORROS | O13: PRESUPUESTO | P13: REAL
B14: Empleo | F14: Alquiler | J14: Ropa | L14: =SUMIFS(Tabla_Gastos367891011[MONTO],Tabla_Gastos367891011[FECHA],">="&$C$1,Tabla_Gastos367891011[FECHA],"<="&$D$1,Tabla_Gastos367891011[CATEGORIA],J14) -> 0 | N14: Compra de casa
B15: Youtube | F15: Internet | J15: Restaurantes | L15: =SUMIFS(Tabla_Gastos367891011[MONTO],Tabla_Gastos367891011[FECHA],">="&$C$1,Tabla_Gastos367891011[FECHA],"<="&$D$1,Tabla_Gastos367891011[CATEGORIA],J15) -> 0 | N15: Viaje a Europa
B16: Ventas en línea | F16: Teléfono | J16: Regalos | L16: =SUMIFS(Tabla_Gastos367891011[MONTO],Tabla_Gastos367891011[FECHA],">="&$C$1,Tabla_Gastos367891011[FECHA],"<="&$D$1,Tabla_Gastos367891011[CATEGORIA],J16) -> 0 | N16: Emergencias
F17: Célular | J17: Transporte | L17: =SUMIFS(Tabla_Gastos367891011[MONTO],Tabla_Gastos367891011[FECHA],">="&$C$1,Tabla_Gastos367891011[FECHA],"<="&$D$1,Tabla_Gastos367891011[CATEGORIA],J17) -> 0
F18: Agua | J18: Entretenimiento | L18: =SUMIFS(Tabla_Gastos367891011[MONTO],Tabla_Gastos367891011[FECHA],">="&$C$1,Tabla_Gastos367891011[FECHA],"<="&$D$1,Tabla_Gastos367891011[CATEGORIA],J18) -> 0
F19: Eléctricidad | J19: Paseos | L19: =SUMIFS(Tabla_Gastos367891011[MONTO],Tabla_Gastos367891011[FECHA],">="&$C$1,Tabla_Gastos367891011[FECHA],"<="&$D$1,Tabla_Gastos367891011[CATEGORIA],J19) -> 0
F20: Gas Doméstico | J20: Médico | L20: =SUMIFS(Tabla_Gastos367891011[MONTO],Tabla_Gastos367891011[FECHA],">="&$C$1,Tabla_Gastos367891011[FECHA],"<="&$D$1,Tabla_Gastos367891011[CATEGORIA],J20) -> 0
F21: Garaje | J21: Mascotas | L21: =SUMIFS(Tabla_Gastos367891011[MONTO],Tabla_Gastos367891011[FECHA],">="&$C$1,Tabla_Gastos367891011[FECHA],"<="&$D$1,Tabla_Gastos367891011[CATEGORIA],J21) -> 0
F22: Gasolina | L22: =SUMIFS(Tabla_Gastos367891011[MONTO],Tabla_Gastos367891011[FECHA],">="&$C$1,Tabla_Gastos367891011[FECHA],"<="&$D$1,Tabla_Gastos367891011[CATEGORIA],J22) -> 0
F23: Netflix | L23: =SUMIFS(Tabla_Gastos367891011[MONTO],Tabla_Gastos367891011[FECHA],">="&$C$1,Tabla_Gastos367891011[FECHA],"<="&$D$1,Tabla_Gastos367891011[CATEGORIA],J23) -> 0
F24: Página Web | L24: =SUMIFS(Tabla_Gastos367891011[MONTO],Tabla_Gastos367891011[FECHA],">="&$C$1,Tabla_Gastos367891011[FECHA],"<="&$D$1,Tabla_Gastos367891011[CATEGORIA],J24) -> 0
